<?xml version="1.0" ?>
<robot name="baxter_gripper">

  <!-- Base of end effector -->
  <link name="gripper_base">
    <visual>
      <origin rpy="-1.57079632679 3.14159265359 0" xyz="0 0 0"/>
      <geometry>
        <mesh filename="package://rethink_ee_description/meshes/electric_gripper/electric_gripper_base.DAE"/>
      </geometry>
    </visual>
    <collision>
      <origin rpy="-1.57079632679 3.14159265359 0" xyz="0.0 0.0 0"/>
      <geometry>
        <cylinder length="0.1" radius="0.029"/>
      </geometry>
      <material name="darkred">
        <color rgba=".5 .1 .1 1"/>
      </material>
    </collision>
    <inertial>
      <origin rpy="-1.57079632679 3.14159265359 0" xyz="0.0 0.0 0.0"/>
      <mass value="0.3"/>
      <inertia ixx="2e-08" ixy="0" ixz="0" iyy="3e-08" iyz="0" izz="2e-08"/>
    </inertial>
  </link>
  <link name="gripper_l_finger">
    <visual>
      <origin rpy="0 0 -3.14159265359" xyz="0 0 0"/>
      <geometry>
        <mesh filename="package://rethink_ee_description/meshes/electric_gripper/fingers/extended_narrow.DAE"/>
      </geometry>
    </visual>
    <collision>
      <origin rpy="0 0 -3.14159265359" xyz="0 0.01725 0.0615"/>
      <geometry>
        <box size="0.01 0.0135 0.1127"/>
      </geometry>
    </collision>
    <collision>
      <origin rpy="0 0 -3.14159265359" xyz="-0.005 -0.003 0.0083"/>
      <geometry>
        <box size="0.01 0.05 0.017"/>
      </geometry>
    </collision>
    <inertial>
      <origin rpy="0 0 -3.14159265359" xyz="0 0 0"/>
      <mass value="0.02"/>
      <inertia ixx="0.01" ixy="0" ixz="0" iyy="0.01" iyz="0" izz="0.01"/>
    </inertial>
  </link>
  <gazebo reference="gripper_l_finger">
    <mu1>1000</mu1>
    <mu2>1000</mu2>
    <fdir1>0.0 0.0 1.0</fdir1>
    <kp>1e5</kp>
    <kd>1.0</kd>
  </gazebo>
  <link name="gripper_l_finger_tip">
    <visual>
      <origin rpy="0 0 3.14159265359" xyz="0 0 0"/>
      <geometry>
        <mesh filename="package://rethink_ee_description/meshes/electric_gripper/fingers/half_round_tip.DAE"/>
      </geometry>
    </visual>
    <collision>
      <origin rpy="0 0 3.14159265359" xyz="0 -0.0045 -0.015"/>
      <geometry>
        <cylinder length="0.037" radius="0.008"/>
      </geometry>
    </collision>
    <inertial>
      <origin rpy="0 0 3.14159265359" xyz="0 0 0"/>
      <mass value="0.01"/>
      <inertia ixx="0.01" ixy="0" ixz="0" iyy="0.01" iyz="0" izz="0.01"/>
    </inertial>
  </link>
  <joint name="gripper_l_finger_tip_joint" type="fixed">
    <origin rpy="0 0 0" xyz="0.0 0.01725 0.1127"/>
    <parent link="gripper_l_finger"/>
    <child link="gripper_l_finger_tip"/>
  </joint>
  <link name="gripper_r_finger">
    <visual>
      <origin rpy="0 0 -0.0" xyz="0 0 0"/>
      <geometry>
        <mesh filename="package://rethink_ee_description/meshes/electric_gripper/fingers/extended_narrow.DAE"/>
      </geometry>
    </visual>
    <collision>
      <origin rpy="0 0 -0.0" xyz="0 -0.01725 0.0615"/>
      <geometry>
        <box size="0.01 0.0135 0.1127"/>
      </geometry>
    </collision>
    <collision>
      <origin rpy="0 0 -0.0" xyz="0.005 0.003 0.0083"/>
      <geometry>
        <box size="0.01 0.05 0.017"/>
      </geometry>
    </collision>
    <inertial>
      <origin rpy="0 0 -0.0" xyz="0 0 0"/>
      <mass value="0.02"/>
      <inertia ixx="0.01" ixy="0" ixz="0" iyy="0.01" iyz="0" izz="0.01"/>
    </inertial>
  </link>
  <gazebo reference="gripper_r_finger">
    <mu1>1000</mu1>
    <mu2>1000</mu2>
    <fdir1>0.0 0.0 1.0</fdir1>
    <kp>1e5</kp>
    <kd>1.0</kd>
  </gazebo>
  <link name="gripper_r_finger_tip">
    <visual>
      <origin rpy="0 0 0.0" xyz="0 0 0"/>
      <geometry>
        <mesh filename="package://rethink_ee_description/meshes/electric_gripper/fingers/half_round_tip.DAE"/>
      </geometry>
    </visual>
    <collision>
      <origin rpy="0 0 0.0" xyz="0 0.0045 -0.015"/>
      <geometry>
        <cylinder length="0.037" radius="0.008"/>
      </geometry>
    </collision>
    <inertial>
      <origin rpy="0 0 0.0" xyz="0 0 0"/>
      <mass value="0.01"/>
      <inertia ixx="0.01" ixy="0" ixz="0" iyy="0.01" iyz="0" izz="0.01"/>
    </inertial>
  </link>
  <joint name="gripper_r_finger_tip_joint" type="fixed">
    <origin rpy="0 0 0" xyz="0.0 -0.01725 0.1127"/>
    <parent link="gripper_r_finger"/>
    <child link="gripper_r_finger_tip"/>
  </joint>

  <!-- Electric Gripper Tip joint -->
  <joint name="endpoint" type="fixed">
    <origin rpy="0 0 0" xyz="0 0 0.1327"/>
    <parent link="gripper_base"/>
    <child link="gripper"/>
  </joint>
  <!-- Electric Gripper Tip link -->
  <link name="gripper">
    <inertial>
      <origin rpy="0 0 0" xyz="0 0 0"/>
      <mass value="0.0001"/>
      <inertia ixx="0" ixy="0" ixz="0" iyy="0" iyz="0" izz="0.0"/>
    </inertial>
  </link>
  <joint name="gripper_l_finger_joint" type="prismatic">
    <origin rpy="0 0 0" xyz="0.0 -0.0015 0.02"/>
    <axis xyz="0 1 0"/>
    <parent link="gripper_base"/>
    <child link="gripper_l_finger"/>
    <limit effort="20.0" lower="0.0" upper="0.020833" velocity="5.0"/>
    <dynamics damping="0.7" friction="0.0"/>
  </joint>
  <joint name="gripper_r_finger_joint" type="prismatic">
    <origin rpy="0 0 0" xyz="0.0 0.0015 0.02"/>
    <axis xyz="0 1 0"/>
    <parent link="gripper_base"/>
    <child link="gripper_r_finger"/>
    <limit effort="20.0" lower="-0.020833" upper="0.0" velocity="5.0"/>
    <mimic joint="gripper_l_finger_joint" multiplier="-1.0"/>
    <dynamics damping="0.7" friction="0.0"/>
  </joint>

  <!-- Transmissions -->
  <transmission name="gripper_right1">
    <type>transmission_interface/SimpleTransmission</type>
    <joint name="gripper_r_finger_joint">
      <hardwareInterface>EffortJointInterface</hardwareInterface>
    </joint>
    <actuator name="gripper_r1_motor1">
      <hardwareInterface>EffortJointInterface</hardwareInterface>
      <mechanicalReduction>1</mechanicalReduction>
    </actuator>
  </transmission>
  <transmission name="gripper_right2">
    <type>transmission_interface/SimpleTransmission</type>
    <joint name="gripper_l_finger_joint">
      <hardwareInterface>EffortJointInterface</hardwareInterface>
    </joint>
    <actuator name="gripper_r1_motor2">
      <hardwareInterface>EffortJointInterface</hardwareInterface>
      <mechanicalReduction>1</mechanicalReduction>
    </actuator>
  </transmission>

  <!-- Virtual joints for floating behaviour -->
  <link name="world"/>
  <joint name="virtual_prismatic_joint" type="prismatic">
    <origin rpy="0 0 0" xyz="0 0 0"/>
    <axis xyz="0 0 1"/>
    <parent link="world"/>
    <child link="gripper_base"/>
    <limit effort="20.0" lower="0.0" upper="0.5" velocity="5.0"/>
    <dynamics damping="0.01" friction="0.0"/>
  </joint>

  <!-- Gazebo gripper plugin -->
  <gazebo>
    <plugin name="gripper_plugin" filename="libGripperPlugin.so">
      <!-- Reference names -->
      <model>baxter_gripper</model>
      <baseLink>gripper_base</baseLink>
      <leftLink>gripper_l_finger</leftLink>
      <rightLink>gripper_r_finger</rightLink>
      <leftJoint>gripper_l_finger_joint</leftJoint>
      <rightJoint>gripper_r_finger_joint</rightJoint>
      <!-- Constraints -->
      <gravity>0</gravity>
    </plugin>
  </gazebo>

  <!-- Gazebo -->
  <gazebo reference="gripper_r_finger_joint">
    <implicitSpringDamper>1</implicitSpringDamper>
  </gazebo>
  <gazebo reference="gripper_l_finger_joint">
    <implicitSpringDamper>1</implicitSpringDamper>
  </gazebo>

</robot>
