<?xml version="1.0" ?>
<!-- =================================================================================== -->
<!-- |    This document was autogenerated by xacro from /home/borrego/catkin_ws/src/sr_common/sr_description/robots/shadowhand_motor.urdf.xacro | -->
<!-- |    EDITING THIS FILE BY HAND IS NOT RECOMMENDED                                 | -->
<!-- =================================================================================== -->
<robot name="shadowhand" xmlns:body="http://playerstage.sourceforge.net/gazebo/xmlschema/#body" xmlns:controller="http://playerstage.sourceforge.net/gazebo/xmlschema/#controller" xmlns:geom="http://playerstage.sourceforge.net/gazebo/xmlschema/#geom" xmlns:interface="http://playerstage.sourceforge.net/gazebo/xmlschema/#interface" xmlns:joint="http://playerstage.sourceforge.net/gazebo/xmlschema/#slider" xmlns:sensor="http://playerstage.sourceforge.net/gazebo/xmlschema/#sensor" xmlns:xacro="http://www.ros.org/wiki/xacro">
  <material name="Blue">
    <color rgba="0.0 0.0 0.8 1.0"/>
  </material>
  <material name="Green">
    <color rgba="0.0 0.8 0.0 1.0"/>
  </material>
  <material name="BiotacGreen">
    <color rgba="0.31 0.85 0.42 1.0"/>
  </material>
  <material name="Grey">
    <color rgba="0.2 0.2 0.2 1.0"/>
  </material>
  <material name="LightGrey">
    <color rgba="0.6 0.6 0.6 1.0"/>
  </material>
  <material name="Red">
    <color rgba="0.8 0.0 0.0 1.0"/>
  </material>
  <material name="White">
    <color rgba="1.0 1.0 1.0 1.0"/>
  </material>

  <!-- Gazebo hand plugin -->
  <gazebo>
    <plugin name="hand_plugin" filename="libHandPlugin.so">
      <!-- Reference names -->
      <model>shadowhand</model>
      <!-- Fingers -->
      <actuatedJoint name="rh_FFJ4"/>
      <actuatedJoint name="rh_FFJ3"/>
      <actuatedJoint name="rh_FFJ2">
        <mimicJoint name="rh_FFJ1" multiplier="0.5" />
      </actuatedJoint>
      <actuatedJoint name="rh_MFJ4"/>
      <actuatedJoint name="rh_MFJ3"/>
      <actuatedJoint name="rh_MFJ2">
        <mimicJoint name="rh_MFJ1" multiplier="0.5" />
      </actuatedJoint>
      <actuatedJoint name="rh_RFJ4"/>
      <actuatedJoint name="rh_RFJ3"/>
      <actuatedJoint name="rh_RFJ2">
        <mimicJoint name="rh_RFJ1" multiplier="0.5" />
      </actuatedJoint>
      <actuatedJoint name="rh_LFJ5"/>
      <actuatedJoint name="rh_LFJ4"/>
      <actuatedJoint name="rh_LFJ3"/>
      <actuatedJoint name="rh_LFJ2">
        <mimicJoint name="rh_LFJ1" multiplier="0.5" />
      </actuatedJoint>
      <actuatedJoint name="rh_THJ5"/>
      <actuatedJoint name="rh_THJ4"/>
      <actuatedJoint name="rh_THJ3"/>
      <actuatedJoint name="rh_THJ2">
        <mimicJoint name="rh_THJ1" multiplier="0.5" />
      </actuatedJoint>
      <!-- Virtual joints for floating behaviour -->
      <virtualJoints min="-1.0" max="1.0">
        virtual_px_joint virtual_py_joint virtual_pz_joint
        virtual_rr_joint virtual_rp_joint virtual_ry_joint
      </virtualJoints>
      <!-- PID controller parameters -->
      <controllers>
        <!-- PID parameters for real hand joints -->
        <real type="position" p="3.0" i="0.0" d="0.0"/>
        <!-- PID parameters for virtual joints -->
        <virtual type="velocity" p="10.0" i="0.0" d="0.0"/>
      </controllers>
      <!-- Constraints -->
      <gravity>1</gravity>
    </plugin>
  </gazebo>

  <!-- Virtual joints for floating behaviour -->
  
  <!-- Virtual link world -->
  <link name="world"/>

  <!-- Translation -->
  <joint name="virtual_px_joint" type="prismatic">
    <origin rpy="0 0 0" xyz="0 0 0"/>
    <axis xyz="1 0 0"/>
    <parent link="world"/>
    <child link="virtual_px_link"/>
    <limit effort="5.0" lower="-0.5" upper="0.5" velocity="5.0"/>
    <dynamics damping="600.0" friction="10.0"/>
  </joint>
  <link name="virtual_px_link">
    <visual>
      <origin rpy="0 0 0.0" xyz="0 0 0"/>
      <geometry>
        <cylinder length="0.01" radius="0.005"/>
      </geometry>
    </visual>
    <inertial>
      <origin rpy="0 0 0" xyz="0.0 0.0 0.0"/>
      <mass value="0.001"/>
      <inertia ixx="0.01" ixy="0" ixz="0" iyy="0.01" iyz="0" izz="0.01"/>
    </inertial>
    <collision>
      <origin rpy="0 0 0" xyz="0.0 0.0 -20.0"/>
      <geometry>
        <cylinder length="0.001" radius="0.005"/>
      </geometry>
    </collision>
  </link>
    <joint name="virtual_py_joint" type="prismatic">
    <origin rpy="0 0 0" xyz="0 0 0"/>
    <axis xyz="0 1 0"/>
    <parent link="virtual_px_link"/>
    <child link="virtual_py_link"/>
    <limit effort="5.0" lower="-0.5" upper="0.5" velocity="5.0"/>
    <dynamics damping="600.0" friction="10.0"/>
  </joint>
  <link name="virtual_py_link">
    <visual>
      <origin rpy="0 0 0.0" xyz="0 0 0"/>
      <geometry>
        <cylinder length="0.01" radius="0.005"/>
      </geometry>
    </visual>
    <inertial>
      <origin rpy="0 0 0" xyz="0.0 0.0 0.0"/>
      <mass value="0.001"/>
      <inertia ixx="0.01" ixy="0" ixz="0" iyy="0.01" iyz="0" izz="0.01"/>
    </inertial>
    <collision>
      <origin rpy="0 0 0" xyz="0.0 0.0 -20.0"/>
      <geometry>
        <cylinder length="0.001" radius="0.005"/>
      </geometry>
    </collision>
  </link>
  <joint name="virtual_pz_joint" type="prismatic">
    <origin rpy="0 0 0" xyz="0 0 0"/>
    <axis xyz="0 0 1"/>
    <parent link="virtual_py_link"/>
    <child link="virtual_pz_link"/>
    <limit effort="20.0" lower="0.0" upper="1.0" velocity="20.0"/>
    <dynamics damping="50.0" friction="0.0"/>
  </joint>
  <link name="virtual_pz_link">
    <visual>
      <origin rpy="0 0 0.0" xyz="0 0 0"/>
      <geometry>
        <cylinder length="0.01" radius="0.005"/>
      </geometry>
    </visual>
    <inertial>
      <origin rpy="0 0 0" xyz="0.0 0.0 0.0"/>
      <mass value="0.001"/>
      <inertia ixx="0.01" ixy="0" ixz="0" iyy="0.01" iyz="0" izz="0.01"/>
    </inertial>
    <collision>
      <origin rpy="0 0 0" xyz="0.0 0.0 -20.0"/>
      <geometry>
        <cylinder length="0.001" radius="0.005"/>
      </geometry>
    </collision>
  </link>

  <!-- Rotation -->
  <joint name="virtual_ry_joint" type="revolute">
    <origin rpy="0 0 0" xyz="0 0 0"/>
    <axis xyz="0 0 1"/>
    <parent link="virtual_pz_link"/>
    <child link="virtual_ry_link"/>
    <limit lower="-1.57" upper="1.57" effort="10.01" velocity="0.0"/>
    <dynamics damping="100000" friction="10.0"/>
  </joint>
  <link name="virtual_ry_link">
    <visual>
      <origin rpy="0 0 0.0" xyz="0 0 0"/>
      <geometry>
        <cylinder length="0.01" radius="0.005"/>
      </geometry>
    </visual>
    <inertial>
      <origin rpy="0 0 0" xyz="0.0 0.0 0.0"/>
      <mass value="0.001"/>
      <inertia ixx="0.01" ixy="0" ixz="0" iyy="0.01" iyz="0" izz="0.01"/>
    </inertial>
    <collision>
      <origin rpy="0 0 0" xyz="0.0 0.0 -20.0"/>
      <geometry>
        <cylinder length="0.001" radius="0.005"/>
      </geometry>
    </collision>
  </link>
    <joint name="virtual_rp_joint" type="revolute">
    <origin rpy="0 0 0" xyz="0 0 0"/>
    <axis xyz="0 1 0"/>
    <parent link="virtual_ry_link"/>
    <child link="virtual_rp_link"/>
    <limit lower="-1.57" upper="1.57" effort="10.01" velocity="0.0"/>
    <dynamics damping="100000" friction="10.0"/>
  </joint>
  <link name="virtual_rp_link">
    <visual>
      <origin rpy="0 0 0.0" xyz="0 0 0"/>
      <geometry>
        <cylinder length="0.01" radius="0.005"/>
      </geometry>
    </visual>
    <inertial>
      <origin rpy="0 0 0" xyz="0.0 0.0 0.0"/>
      <mass value="0.001"/>
      <inertia ixx="0.01" ixy="0" ixz="0" iyy="0.01" iyz="0" izz="0.01"/>
    </inertial>
    <collision>
      <origin rpy="0 0 0" xyz="0.0 0.0 -20.0"/>
      <geometry>
        <cylinder length="0.001" radius="0.005"/>
      </geometry>
    </collision>
  </link>
    <joint name="virtual_rr_joint" type="revolute">
    <origin rpy="0 0 0" xyz="0 0 0"/>
    <axis xyz="1 0 0"/>
    <parent link="virtual_rp_link"/>
    <child link="base_footprint"/>
    <limit lower="-1.57" upper="1.57" effort="10.01" velocity="0.0"/>
    <dynamics damping="100000" friction="10.0"/>
  </joint>

  <!-- Root link, on the ground just below the robot origin -->
  <link name="base_footprint"/>

  <joint name="rh_base_joint" type="fixed">
    <parent link="base_footprint"/>
    <child link="rh_palm"/>
    <origin rpy="0.0 0.0 0.0" xyz="0.0 0.0 0.0"/>
  </joint>

  <link name="rh_palm">
    <inertial>
      <origin rpy="0 0 0" xyz="0 0 0.035"/>
      <mass value="0.3"/>
      <inertia ixx="0.0003581" ixy="0.0" ixz="0.0" iyy="0.0005287" iyz="0.0" izz="0.000191"/>
    </inertial>
    <visual>
      <origin rpy="0 0 0" xyz="0 0 0"/>
      <geometry name="rh_palm_visual">
        <mesh filename="package://sr_description/hand/model/palm.dae" scale="0.001 0.001 0.001"/>
      </geometry>
      <material name="Grey"/>
    </visual>
    <collision>
      <origin rpy="0 0 0" xyz="0.011 0.0085 0.038"/>
      <geometry name="rh_palm_collision_geom">
        <box size="0.062 0.007 0.098"/>
      </geometry>
    </collision>
    <collision>
      <origin rpy="0 0 0" xyz="-0.002 -0.0035 0.038"/>
      <geometry>
        <box size="0.036 0.017 0.098"/>
      </geometry>
    </collision>
    <!-- palm complement below first finger -->
    <collision>
      <origin rpy="0 0 0" xyz="0.029 -0.0035 0.082"/>
      <geometry>
        <box size="0.026 0.017 0.010"/>
      </geometry>
    </collision>
    <collision>
      <origin rpy="0.2 0 0.25" xyz="0.0265 -0.001 0.070"/>
      <geometry>
        <box size="0.026 0.014 0.018"/>
      </geometry>
    </collision>
    <!-- thumb pulp side -->
    <collision>
      <origin rpy="0 0 0" xyz="0.0315 -0.0085 0.001"/>
      <geometry>
        <box size="0.021 0.027 0.024"/>
      </geometry>
    </collision>
    <!-- thumb pulp central -->
    <collision>
      <origin rpy="0 0 -0.48" xyz="0.0125 -0.015 0.009"/>
      <geometry>
        <box size="0.022 0.005 0.040"/>
      </geometry>
    </collision>
    <!-- above middle finger-->
    <collision>
      <origin rpy="0 0 0" xyz="0.011 0 0.089"/>
      <geometry>
        <box size="0.018 0.024 0.004"/>
      </geometry>
    </collision>
    <!-- metacarpal side-->
    <collision>
      <origin rpy="0 0 0" xyz="-0.03 0 0.009"/>
      <geometry>
        <box size="0.020 0.024 0.040"/>
      </geometry>
    </collision>
  </link>

  <link name="rh_imu"/>
  <joint name="rh_palm_to_imu" type="fixed">
    <parent link="rh_palm"/>
    <child link="rh_imu"/>
    <origin rpy="-1.5707963 3.141592 0.0" xyz="0.01785 0.00765 0.049125"/>
  </joint>

  <link name="rh_ffknuckle">
    <inertial>
      <origin rpy="0 0 0" xyz="0 0 0"/>
      <mass value="0.008"/>
      <inertia ixx="0.00000026" ixy="0.0" ixz="0.0" iyy="0.00000026" iyz="0.0" izz="0.00000032"/>
    </inertial>
    <visual>
      <origin rpy="0 0 0" xyz="0 0 0.0005"/>
      <geometry name="rh_ffknuckle_visual">
        <mesh filename="package://sr_description/hand/model/knuckle.dae" scale="0.001 0.001 0.001"/>
      </geometry>
      <material name="LightGrey"/>
    </visual>
    <collision>
      <origin rpy="0 1.5708 0" xyz="0 0 0"/>
      <geometry name="rh_ffknuckle_collision_geom">
        <cylinder length="0.014" radius="0.007"/>
      </geometry>
    </collision>
  </link>
  <joint name="rh_FFJ4" type="revolute">
    <parent link="rh_palm"/>
    <child link="rh_ffknuckle"/>
    <!--<origin xyz="0.033 0 0.095" rpy="0 0 0" />-->
    <origin rpy="0 0 0" xyz="0.033 0 0.095"/>
    <axis xyz="0 -1.0 0"/>
    <limit effort="2" lower="-0.349065850399" upper="0.349065850399" velocity="2.0"/>
    <dynamics damping="0.1"/>
  </joint>

  <!-- prefix can be anything but usually is "r_" or  "l_" for right and left hands distinction -->
  <gazebo reference="rh_ffknuckle">
    <material>Gazebo/Grey</material>
  </gazebo>
  <link name="rh_ffproximal">
    <inertial>
      <mass value="0.030"/>
      <origin xyz="0 0 0.0225"/>
      <inertia ixx="0.0000098" ixy="0.0" ixz="0.0" iyy="0.00001" iyz="0.0" izz="0.0000018"/>
    </inertial>
    <visual>
      <origin rpy="0 0 0" xyz="0 0 0"/>
      <geometry name="rh_ffproximal_visual">
        <mesh filename="package://sr_description/hand/model/F3.dae" scale="0.001 0.001 0.001"/>
      </geometry>
      <material name="Grey"/>
    </visual>
    <collision>
      <origin rpy="0 0 0" xyz="0 0 0.025"/>
      <geometry name="rh_ffproximal_collision_geom">
        <cylinder length="0.040" radius="0.007"/>
      </geometry>
    </collision>
  </link>
  <joint name="rh_FFJ3" type="revolute">
    <parent link="rh_ffknuckle"/>
    <child link="rh_ffproximal"/>
    <origin rpy="0 0 0" xyz="0 0 0"/>
    <axis xyz="1 0 0"/>
    <limit effort="2" lower="0" upper="1.57079632679" velocity="2.0"/>
    <dynamics damping="0.1"/>
  </joint>

  <!-- prefix can be anything but usually is "r_" or  "l_" for right and left hands distinction -->
  <gazebo reference="rh_ffproximal">
    <selfCollide>true</selfCollide>
  </gazebo>
  <link name="rh_ffmiddle">
    <inertial>
      <origin rpy="0 0 0" xyz="0 0 0.0125"/>
      <mass value="0.017"/>
      <inertia ixx="0.0000026" ixy="0.0" ixz="0.0" iyy="0.0000027" iyz="0.0" izz="0.00000087"/>
    </inertial>
    <visual>
      <origin rpy="0 0 0" xyz="0 0 0"/>
      <geometry name="rh_ffmiddle_visual">
        <mesh filename="package://sr_description/hand/model/F2.dae" scale="0.001 0.001 0.001"/>
      </geometry>
      <material name="Grey"/>
    </visual>
    <collision>
      <origin rpy="0 0 0" xyz="0 0 0.0125"/>
      <geometry name="rh_ffmiddle_collision_geom">
        <cylinder length="0.025" radius="0.007"/>
      </geometry>
    </collision>
    <collision>
      <origin rpy="0 0 0" xyz="0 0 0.0"/>
      <geometry>
        <sphere radius="0.007"/>
      </geometry>
    </collision>
    <collision>
      <origin rpy="0 0 0" xyz="0 0 0.025"/>
      <geometry>
        <sphere radius="0.007"/>
      </geometry>
    </collision>
  </link>
  <joint name="rh_FFJ2" type="revolute">
    <parent link="rh_ffproximal"/>
    <child link="rh_ffmiddle"/>
    <origin rpy="0 0 0" xyz="0 0 0.045"/>
    <axis xyz="1 0 0"/>
    <limit effort="2" lower="0" upper="1.57079632679" velocity="2.0"/>
    <dynamics damping="0.1"/>
  </joint>

  <!-- prefix can be anything but usually is "r_" or  "l_" for right and left hands distinction -->
  <gazebo reference="rh_ffmiddle">
    <selfCollide>true</selfCollide>
  </gazebo>
  <link name="rh_ffdistal">
    <inertial>
      <mass value="0.012"/>
      <origin xyz="0 0 0.012"/>
      <inertia ixx="0.00000094" ixy="0.0" ixz="0.0" iyy="0.0000011" iyz="0.0" izz="0.00000053"/>
    </inertial>
    <visual>
      <origin rpy="0 0 0" xyz="0 0 0"/>
      <geometry name="rh_ffdistal_visual">
        <!-- Standard distal  -->
        <mesh filename="package://sr_description/hand/model/F1.dae" scale="0.001 0.001 0.001"/>
      </geometry>
      <material name="Grey"/>
    </visual>
    <collision>
      <origin rpy="0 0 0" xyz="0 0 0"/>
      <geometry name="rh_ffdistal_collision_geom">
        <!-- Standard distal  -->
        <mesh filename="package://sr_description/hand/model/F1.dae" scale="0.001 0.001 0.001"/>
      </geometry>
    </collision>
  </link>
  <joint name="rh_FFJ1" type="revolute">
    <parent link="rh_ffmiddle"/>
    <child link="rh_ffdistal"/>
    <origin rpy="0 0 0" xyz="0 0 0.025"/>
    <axis xyz="1 0 0"/>
    <!-- standard distal joint -->
    <limit effort="2" lower="0" upper="1.57079632679" velocity="2.0"/>
    <dynamics damping="0.1"/>
  </joint>
  <gazebo reference="rh_FFJ1">
    <provideFeedback>1</provideFeedback>
    <implicitSpringDamper>1</implicitSpringDamper>
  </gazebo>
  <link name="rh_fftip">
    <inertial>
      <mass value="0.001"/>
      <inertia ixx="0.0" ixy="0.0" ixz="0.0" iyy="0.0" iyz="0.0" izz="0.0"/>
    </inertial>
  </link>
  <joint name="rh_FFtip" type="fixed">
    <parent link="rh_ffdistal"/>
    <child link="rh_fftip"/>
    <origin rpy="0 0 0" xyz="0 0 0.026"/>
  </joint>
  <!-- prefix can be anything but usually is "r_" or  "l_" for right and left hands distinction -->
  <gazebo reference="rh_ffdistal">
    <mu1 value="500.0"/>
    <mu2 value="500.0"/>
    <kp value="10000000.0"/>
    <kd value="1.0"/>
    <selfCollide>true</selfCollide>
  </gazebo>
  <link name="rh_mfknuckle">
    <inertial>
      <origin rpy="0 0 0" xyz="0 0 0"/>
      <mass value="0.008"/>
      <inertia ixx="0.00000026" ixy="0.0" ixz="0.0" iyy="0.00000026" iyz="0.0" izz="0.00000032"/>
    </inertial>
    <visual>
      <origin rpy="0 0 0" xyz="0 0 0.0005"/>
      <geometry name="rh_mfknuckle_visual">
        <mesh filename="package://sr_description/hand/model/knuckle.dae" scale="0.001 0.001 0.001"/>
      </geometry>
      <material name="LightGrey"/>
    </visual>
    <collision>
      <origin rpy="0 1.5708 0" xyz="0 0 0"/>
      <geometry name="rh_mfknuckle_collision_geom">
        <cylinder length="0.014" radius="0.007"/>
      </geometry>
    </collision>
  </link>
  <joint name="rh_MFJ4" type="revolute">
    <parent link="rh_palm"/>
    <child link="rh_mfknuckle"/>
    <!--<origin xyz="0.033 0 0.095" rpy="0 0 0" />-->
    <origin rpy="0 0 0" xyz="0.011 0 0.099"/>
    <axis xyz="0 -1.0 0"/>
    <limit effort="2" lower="-0.349065850399" upper="0.349065850399" velocity="2.0"/>
    <dynamics damping="0.1"/>
  </joint>

  <!-- prefix can be anything but usually is "r_" or  "l_" for right and left hands distinction -->
  <gazebo reference="rh_mfknuckle">
    <material>Gazebo/Grey</material>
  </gazebo>
  <link name="rh_mfproximal">
    <inertial>
      <mass value="0.030"/>
      <origin xyz="0 0 0.0225"/>
      <inertia ixx="0.0000098" ixy="0.0" ixz="0.0" iyy="0.00001" iyz="0.0" izz="0.0000018"/>
    </inertial>
    <visual>
      <origin rpy="0 0 0" xyz="0 0 0"/>
      <geometry name="rh_mfproximal_visual">
        <mesh filename="package://sr_description/hand/model/F3.dae" scale="0.001 0.001 0.001"/>
      </geometry>
      <material name="Grey"/>
    </visual>
    <collision>
      <origin rpy="0 0 0" xyz="0 0 0.025"/>
      <geometry name="rh_mfproximal_collision_geom">
        <cylinder length="0.040" radius="0.007"/>
      </geometry>
    </collision>
  </link>
  <joint name="rh_MFJ3" type="revolute">
    <parent link="rh_mfknuckle"/>
    <child link="rh_mfproximal"/>
    <origin rpy="0 0 0" xyz="0 0 0"/>
    <axis xyz="1 0 0"/>
    <limit effort="2" lower="0" upper="1.57079632679" velocity="2.0"/>
    <dynamics damping="0.1"/>
  </joint>

  <!-- prefix can be anything but usually is "r_" or  "l_" for right and left hands distinction -->
  <gazebo reference="rh_mfproximal">
    <selfCollide>true</selfCollide>
  </gazebo>
  <link name="rh_mfmiddle">
    <inertial>
      <origin rpy="0 0 0" xyz="0 0 0.0125"/>
      <mass value="0.017"/>
      <inertia ixx="0.0000026" ixy="0.0" ixz="0.0" iyy="0.0000027" iyz="0.0" izz="0.00000087"/>
    </inertial>
    <visual>
      <origin rpy="0 0 0" xyz="0 0 0"/>
      <geometry name="rh_mfmiddle_visual">
        <mesh filename="package://sr_description/hand/model/F2.dae" scale="0.001 0.001 0.001"/>
      </geometry>
      <material name="Grey"/>
    </visual>
    <collision>
      <origin rpy="0 0 0" xyz="0 0 0.0125"/>
      <geometry name="rh_mfmiddle_collision_geom">
        <cylinder length="0.025" radius="0.007"/>
      </geometry>
    </collision>
    <collision>
      <origin rpy="0 0 0" xyz="0 0 0.0"/>
      <geometry>
        <sphere radius="0.007"/>
      </geometry>
    </collision>
    <collision>
      <origin rpy="0 0 0" xyz="0 0 0.025"/>
      <geometry>
        <sphere radius="0.007"/>
      </geometry>
    </collision>
  </link>
  <joint name="rh_MFJ2" type="revolute">
    <parent link="rh_mfproximal"/>
    <child link="rh_mfmiddle"/>
    <origin rpy="0 0 0" xyz="0 0 0.045"/>
    <axis xyz="1 0 0"/>
    <limit effort="2" lower="0" upper="1.57079632679" velocity="2.0"/>
    <dynamics damping="0.1"/>
  </joint>

  <!-- prefix can be anything but usually is "r_" or  "l_" for right and left hands distinction -->
  <gazebo reference="rh_mfmiddle">
    <selfCollide>true</selfCollide>
  </gazebo>
  <link name="rh_mfdistal">
    <inertial>
      <mass value="0.012"/>
      <origin xyz="0 0 0.012"/>
      <inertia ixx="0.00000094" ixy="0.0" ixz="0.0" iyy="0.0000011" iyz="0.0" izz="0.00000053"/>
    </inertial>
    <visual>
      <origin rpy="0 0 0" xyz="0 0 0"/>
      <geometry name="rh_mfdistal_visual">
        <!-- Standard distal  -->
        <mesh filename="package://sr_description/hand/model/F1.dae" scale="0.001 0.001 0.001"/>
      </geometry>
      <material name="Grey"/>
    </visual>
    <collision>
      <origin rpy="0 0 0" xyz="0 0 0"/>
      <geometry name="rh_mfdistal_collision_geom">
        <!-- Standard distal  -->
        <mesh filename="package://sr_description/hand/model/F1.dae" scale="0.001 0.001 0.001"/>
      </geometry>
    </collision>
  </link>
  <joint name="rh_MFJ1" type="revolute">
    <parent link="rh_mfmiddle"/>
    <child link="rh_mfdistal"/>
    <origin rpy="0 0 0" xyz="0 0 0.025"/>
    <axis xyz="1 0 0"/>
    <!-- standard distal joint -->
    <limit effort="2" lower="0" upper="1.57079632679" velocity="2.0"/>
    <dynamics damping="0.1"/>
  </joint>
  <gazebo reference="rh_MFJ1">
    <provideFeedback>1</provideFeedback>
    <implicitSpringDamper>1</implicitSpringDamper>
  </gazebo>
  <link name="rh_mftip">
    <inertial>
      <mass value="0.001"/>
      <inertia ixx="0.0" ixy="0.0" ixz="0.0" iyy="0.0" iyz="0.0" izz="0.0"/>
    </inertial>
  </link>
  <joint name="rh_MFtip" type="fixed">
    <parent link="rh_mfdistal"/>
    <child link="rh_mftip"/>
    <origin rpy="0 0 0" xyz="0 0 0.026"/>
  </joint>
  <!-- prefix can be anything but usually is "r_" or  "l_" for right and left hands distinction -->
  <gazebo reference="rh_mfdistal">
    <mu1 value="500.0"/>
    <mu2 value="500.0"/>
    <kp value="10000000.0"/>
    <kd value="1.0"/>
    <selfCollide>true</selfCollide>
  </gazebo>
  <link name="rh_rfknuckle">
    <inertial>
      <origin rpy="0 0 0" xyz="0 0 0"/>
      <mass value="0.008"/>
      <inertia ixx="0.00000026" ixy="0.0" ixz="0.0" iyy="0.00000026" iyz="0.0" izz="0.00000032"/>
    </inertial>
    <visual>
      <origin rpy="0 0 0" xyz="0 0 0.0005"/>
      <geometry name="rh_rfknuckle_visual">
        <mesh filename="package://sr_description/hand/model/knuckle.dae" scale="0.001 0.001 0.001"/>
      </geometry>
      <material name="LightGrey"/>
    </visual>
    <collision>
      <origin rpy="0 1.5708 0" xyz="0 0 0"/>
      <geometry name="rh_rfknuckle_collision_geom">
        <cylinder length="0.014" radius="0.007"/>
      </geometry>
    </collision>
  </link>
  <joint name="rh_RFJ4" type="revolute">
    <parent link="rh_palm"/>
    <child link="rh_rfknuckle"/>
    <!--<origin xyz="0.033 0 0.095" rpy="0 0 0" />-->
    <origin rpy="0 0 0" xyz="-0.011 0 0.095"/>
    <axis xyz="0 1.0 0"/>
    <limit effort="2" lower="-0.349065850399" upper="0.349065850399" velocity="2.0"/>
    <dynamics damping="0.1"/>
  </joint>

  <!-- prefix can be anything but usually is "r_" or  "l_" for right and left hands distinction -->
  <gazebo reference="rh_rfknuckle">
    <material>Gazebo/Grey</material>
  </gazebo>
  <link name="rh_rfproximal">
    <inertial>
      <mass value="0.030"/>
      <origin xyz="0 0 0.0225"/>
      <inertia ixx="0.0000098" ixy="0.0" ixz="0.0" iyy="0.00001" iyz="0.0" izz="0.0000018"/>
    </inertial>
    <visual>
      <origin rpy="0 0 0" xyz="0 0 0"/>
      <geometry name="rh_rfproximal_visual">
        <mesh filename="package://sr_description/hand/model/F3.dae" scale="0.001 0.001 0.001"/>
      </geometry>
      <material name="Grey"/>
    </visual>
    <collision>
      <origin rpy="0 0 0" xyz="0 0 0.025"/>
      <geometry name="rh_rfproximal_collision_geom">
        <cylinder length="0.040" radius="0.007"/>
      </geometry>
    </collision>
  </link>
  <joint name="rh_RFJ3" type="revolute">
    <parent link="rh_rfknuckle"/>
    <child link="rh_rfproximal"/>
    <origin rpy="0 0 0" xyz="0 0 0"/>
    <axis xyz="1 0 0"/>
    <limit effort="2" lower="0" upper="1.57079632679" velocity="2.0"/>
    <dynamics damping="0.1"/>
  </joint>

  <!-- prefix can be anything but usually is "r_" or  "l_" for right and left hands distinction -->
  <gazebo reference="rh_rfproximal">
    <selfCollide>true</selfCollide>
  </gazebo>
  <link name="rh_rfmiddle">
    <inertial>
      <origin rpy="0 0 0" xyz="0 0 0.0125"/>
      <mass value="0.017"/>
      <inertia ixx="0.0000026" ixy="0.0" ixz="0.0" iyy="0.0000027" iyz="0.0" izz="0.00000087"/>
    </inertial>
    <visual>
      <origin rpy="0 0 0" xyz="0 0 0"/>
      <geometry name="rh_rfmiddle_visual">
        <mesh filename="package://sr_description/hand/model/F2.dae" scale="0.001 0.001 0.001"/>
      </geometry>
      <material name="Grey"/>
    </visual>
    <collision>
      <origin rpy="0 0 0" xyz="0 0 0.0125"/>
      <geometry name="rh_rfmiddle_collision_geom">
        <cylinder length="0.025" radius="0.007"/>
      </geometry>
    </collision>
    <collision>
      <origin rpy="0 0 0" xyz="0 0 0.0"/>
      <geometry>
        <sphere radius="0.007"/>
      </geometry>
    </collision>
    <collision>
      <origin rpy="0 0 0" xyz="0 0 0.025"/>
      <geometry>
        <sphere radius="0.007"/>
      </geometry>
    </collision>
  </link>
  <joint name="rh_RFJ2" type="revolute">
    <parent link="rh_rfproximal"/>
    <child link="rh_rfmiddle"/>
    <origin rpy="0 0 0" xyz="0 0 0.045"/>
    <axis xyz="1 0 0"/>
    <limit effort="2" lower="0" upper="1.57079632679" velocity="2.0"/>
    <dynamics damping="0.1"/>
  </joint>

  <!-- prefix can be anything but usually is "r_" or  "l_" for right and left hands distinction -->
  <gazebo reference="rh_rfmiddle">
    <selfCollide>true</selfCollide>
  </gazebo>
  <link name="rh_rfdistal">
    <inertial>
      <mass value="0.012"/>
      <origin xyz="0 0 0.012"/>
      <inertia ixx="0.00000094" ixy="0.0" ixz="0.0" iyy="0.0000011" iyz="0.0" izz="0.00000053"/>
    </inertial>
    <visual>
      <origin rpy="0 0 0" xyz="0 0 0"/>
      <geometry name="rh_rfdistal_visual">
        <!-- Standard distal  -->
        <mesh filename="package://sr_description/hand/model/F1.dae" scale="0.001 0.001 0.001"/>
      </geometry>
      <material name="Grey"/>
    </visual>
    <collision>
      <origin rpy="0 0 0" xyz="0 0 0"/>
      <geometry name="rh_rfdistal_collision_geom">
        <!-- Standard distal  -->
        <mesh filename="package://sr_description/hand/model/F1.dae" scale="0.001 0.001 0.001"/>
      </geometry>
    </collision>
  </link>
  <joint name="rh_RFJ1" type="revolute">
    <parent link="rh_rfmiddle"/>
    <child link="rh_rfdistal"/>
    <origin rpy="0 0 0" xyz="0 0 0.025"/>
    <axis xyz="1 0 0"/>
    <!-- standard distal joint -->
    <limit effort="2" lower="0" upper="1.57079632679" velocity="2.0"/>
    <dynamics damping="0.1"/>
  </joint>
  <gazebo reference="rh_RFJ1">
    <provideFeedback>1</provideFeedback>
    <implicitSpringDamper>1</implicitSpringDamper>
  </gazebo>
  <link name="rh_rftip">
    <inertial>
      <mass value="0.001"/>
      <inertia ixx="0.0" ixy="0.0" ixz="0.0" iyy="0.0" iyz="0.0" izz="0.0"/>
    </inertial>
  </link>
  <joint name="rh_RFtip" type="fixed">
    <parent link="rh_rfdistal"/>
    <child link="rh_rftip"/>
    <origin rpy="0 0 0" xyz="0 0 0.026"/>
  </joint>
  <!-- prefix can be anything but usually is "r_" or  "l_" for right and left hands distinction -->
  <gazebo reference="rh_rfdistal">
    <mu1 value="500.0"/>
    <mu2 value="500.0"/>
    <kp value="10000000.0"/>
    <kd value="1.0"/>
    <selfCollide>true</selfCollide>
  </gazebo>
  <link name="rh_lfmetacarpal">
    <inertial>
      <origin rpy="0 0 0" xyz="0 0 0.04"/>
      <mass value="0.030"/>
      <inertia ixx="0.0000145" ixy="0.0" ixz="0.0" iyy="0.00001638" iyz="0.0" izz="0.000004272"/>
    </inertial>
    <visual>
      <origin rpy="0 0 0" xyz="0 0 0"/>
      <geometry name="rh_lfmetacarpal_visual">
        <mesh filename="package://sr_description/hand/model/lfmetacarpal.dae" scale="0.001 0.001 0.001"/>
      </geometry>
      <material name="Grey"/>
    </visual>
    <collision>
      <origin rpy="0 0 0" xyz="0 0 0.038"/>
      <geometry name="rh_lfmetacarpal_collision_geom">
        <box size="0.018 0.024 0.040"/>
      </geometry>
    </collision>
  </link>
  <joint name="rh_LFJ5" type="revolute">
    <parent link="rh_palm"/>
    <child link="rh_lfmetacarpal"/>
    <origin rpy="0 0 0" xyz="-0.033 0 0.02071"/>
    <axis xyz="0.573576436 0 0.819152044"/>
    <limit effort="2" lower="0" upper="0.785398163397" velocity="2.0"/>
    <dynamics damping="0.1"/>
  </joint>

  <!-- prefix can be anything but usually is "r_" or  "l_" for right and left hands distinction -->
  <gazebo reference="rh_lfmetacarpal">
    <selfCollide>true</selfCollide>
  </gazebo>
  <link name="rh_lfknuckle">
    <inertial>
      <origin rpy="0 0 0" xyz="0 0 0"/>
      <mass value="0.008"/>
      <inertia ixx="0.00000026" ixy="0.0" ixz="0.0" iyy="0.00000026" iyz="0.0" izz="0.00000032"/>
    </inertial>
    <visual>
      <origin rpy="0 0 0" xyz="0 0 0.0005"/>
      <geometry name="rh_lfknuckle_visual">
        <mesh filename="package://sr_description/hand/model/knuckle.dae" scale="0.001 0.001 0.001"/>
      </geometry>
      <material name="LightGrey"/>
    </visual>
    <collision>
      <origin rpy="0 1.5708 0" xyz="0 0 0"/>
      <geometry name="rh_lfknuckle_collision_geom">
        <cylinder length="0.014" radius="0.007"/>
      </geometry>
    </collision>
  </link>
  <joint name="rh_LFJ4" type="revolute">
    <parent link="rh_lfmetacarpal"/>
    <child link="rh_lfknuckle"/>
    <!--<origin xyz="0.033 0 0.095" rpy="0 0 0" />-->
    <origin rpy="0 0 0" xyz="0 0 0.06579"/>
    <axis xyz="0 1.0 0"/>
    <limit effort="2" lower="-0.349065850399" upper="0.349065850399" velocity="2.0"/>
    <dynamics damping="0.1"/>
  </joint>

  <!-- prefix can be anything but usually is "r_" or  "l_" for right and left hands distinction -->
  <gazebo reference="rh_lfknuckle">
    <material>Gazebo/Grey</material>
  </gazebo>
  <link name="rh_lfproximal">
    <inertial>
      <mass value="0.030"/>
      <origin xyz="0 0 0.0225"/>
      <inertia ixx="0.0000098" ixy="0.0" ixz="0.0" iyy="0.00001" iyz="0.0" izz="0.0000018"/>
    </inertial>
    <visual>
      <origin rpy="0 0 0" xyz="0 0 0"/>
      <geometry name="rh_lfproximal_visual">
        <mesh filename="package://sr_description/hand/model/F3.dae" scale="0.001 0.001 0.001"/>
      </geometry>
      <material name="Grey"/>
    </visual>
    <collision>
      <origin rpy="0 0 0" xyz="0 0 0.025"/>
      <geometry name="rh_lfproximal_collision_geom">
        <cylinder length="0.040" radius="0.007"/>
      </geometry>
    </collision>
  </link>
  <joint name="rh_LFJ3" type="revolute">
    <parent link="rh_lfknuckle"/>
    <child link="rh_lfproximal"/>
    <origin rpy="0 0 0" xyz="0 0 0"/>
    <axis xyz="1 0 0"/>
    <limit effort="2" lower="0" upper="1.57079632679" velocity="2.0"/>
    <dynamics damping="0.1"/>
  </joint>

  <!-- prefix can be anything but usually is "r_" or  "l_" for right and left hands distinction -->
  <gazebo reference="rh_lfproximal">
    <selfCollide>true</selfCollide>
  </gazebo>
  <link name="rh_lfmiddle">
    <inertial>
      <origin rpy="0 0 0" xyz="0 0 0.0125"/>
      <mass value="0.017"/>
      <inertia ixx="0.0000026" ixy="0.0" ixz="0.0" iyy="0.0000027" iyz="0.0" izz="0.00000087"/>
    </inertial>
    <visual>
      <origin rpy="0 0 0" xyz="0 0 0"/>
      <geometry name="rh_lfmiddle_visual">
        <mesh filename="package://sr_description/hand/model/F2.dae" scale="0.001 0.001 0.001"/>
      </geometry>
      <material name="Grey"/>
    </visual>
    <collision>
      <origin rpy="0 0 0" xyz="0 0 0.0125"/>
      <geometry name="rh_lfmiddle_collision_geom">
        <cylinder length="0.025" radius="0.007"/>
      </geometry>
    </collision>
    <collision>
      <origin rpy="0 0 0" xyz="0 0 0.0"/>
      <geometry>
        <sphere radius="0.007"/>
      </geometry>
    </collision>
    <collision>
      <origin rpy="0 0 0" xyz="0 0 0.025"/>
      <geometry>
        <sphere radius="0.007"/>
      </geometry>
    </collision>
  </link>
  <joint name="rh_LFJ2" type="revolute">
    <parent link="rh_lfproximal"/>
    <child link="rh_lfmiddle"/>
    <origin rpy="0 0 0" xyz="0 0 0.045"/>
    <axis xyz="1 0 0"/>
    <limit effort="2" lower="0" upper="1.57079632679" velocity="2.0"/>
    <dynamics damping="0.1"/>
  </joint>

  <!-- prefix can be anything but usually is "r_" or  "l_" for right and left hands distinction -->
  <gazebo reference="rh_lfmiddle">
    <selfCollide>true</selfCollide>
  </gazebo>
  <link name="rh_lfdistal">
    <inertial>
      <mass value="0.012"/>
      <origin xyz="0 0 0.012"/>
      <inertia ixx="0.00000094" ixy="0.0" ixz="0.0" iyy="0.0000011" iyz="0.0" izz="0.00000053"/>
    </inertial>
    <visual>
      <origin rpy="0 0 0" xyz="0 0 0"/>
      <geometry name="rh_lfdistal_visual">
        <!-- Standard distal  -->
        <mesh filename="package://sr_description/hand/model/F1.dae" scale="0.001 0.001 0.001"/>
      </geometry>
      <material name="Grey"/>
    </visual>
    <collision>
      <origin rpy="0 0 0" xyz="0 0 0"/>
      <geometry name="rh_lfdistal_collision_geom">
        <!-- Standard distal  -->
        <mesh filename="package://sr_description/hand/model/F1.dae" scale="0.001 0.001 0.001"/>
      </geometry>
    </collision>
  </link>
  <joint name="rh_LFJ1" type="revolute">
    <parent link="rh_lfmiddle"/>
    <child link="rh_lfdistal"/>
    <origin rpy="0 0 0" xyz="0 0 0.025"/>
    <axis xyz="1 0 0"/>
    <!-- standard distal joint -->
    <limit effort="2" lower="0" upper="1.57079632679" velocity="2.0"/>
    <dynamics damping="0.1"/>
  </joint>
  <gazebo reference="rh_LFJ1">
    <provideFeedback>1</provideFeedback>
    <implicitSpringDamper>1</implicitSpringDamper>
  </gazebo>
  <link name="rh_lftip">
    <inertial>
      <mass value="0.001"/>
      <inertia ixx="0.0" ixy="0.0" ixz="0.0" iyy="0.0" iyz="0.0" izz="0.0"/>
    </inertial>
  </link>
  <joint name="rh_LFtip" type="fixed">
    <parent link="rh_lfdistal"/>
    <child link="rh_lftip"/>
    <origin rpy="0 0 0" xyz="0 0 0.026"/>
  </joint>
  <!-- prefix can be anything but usually is "r_" or  "l_" for right and left hands distinction -->
  <gazebo reference="rh_lfdistal">
    <mu1 value="500.0"/>
    <mu2 value="500.0"/>
    <kp value="10000000.0"/>
    <kd value="1.0"/>
    <selfCollide>true</selfCollide>
  </gazebo>
  <link name="rh_thbase">
    <inertial>
      <mass value="0.010"/>
      <origin rpy="0 0 0" xyz="0 0 0"/>
      <inertia ixx="0.00000016" ixy="0.0" ixz="0.0" iyy="0.00000016" iyz="0.0" izz="0.00000016"/>
    </inertial>
    <visual>
      <origin rpy="0 0 0" xyz="0 0 0"/>
      <geometry name="rh_thbase_visual">
        <box size="0.001 0.001 0.001"/>
      </geometry>
      <material name="shadow_thbase_material">
        <color rgba="0.5 0.5 0.5 1.0"/>
      </material>
    </visual>
    <collision>
      <origin rpy="0 0 0" xyz="0 0 0"/>
      <geometry name="rh_thbase_collision_geom">
        <sphere radius="0.011"/>
      </geometry>
    </collision>
  </link>
  <joint name="rh_THJ5" type="revolute">
    <parent link="rh_palm"/>
    <child link="rh_thbase"/>
    <origin rpy="0 0.785398163397 0.0" xyz="0.034 -0.0085 0.029"/>
    <axis xyz="0 0 -1.0"/>
    <limit effort="5.0" lower="-1.0471975512" upper="1.0471975512" velocity="4.0"/>
    <dynamics damping="0.2"/>
  </joint>

  <!-- prefix can be anything but usually is "r_" or  "l_" for right and left hands distinction -->
  <gazebo reference="rh_thbase">
    <selfCollide>false</selfCollide>
  </gazebo>
  <link name="rh_thproximal">
    <inertial>
      <mass value="0.040"/>
      <origin rpy="0 0 0" xyz="0 0 0.019"/>
      <inertia ixx="0.0000136" ixy="0.0" ixz="0.0" iyy="0.0000136" iyz="0.0" izz="0.00000313"/>
    </inertial>
    <visual>
      <origin rpy="0 0 0" xyz="0 0 0"/>
      <geometry name="rh_thproximal_visual">
        <mesh filename="package://sr_description/hand/model/TH3_z.dae" scale="0.001 0.001 0.001"/>
      </geometry>
      <material name="shadow_thproximal_material">
        <color rgba="0.2 0.2 0.2 1.0"/>
      </material>
    </visual>
    <collision>
      <origin rpy="0 0 0" xyz="0 0 0.020"/>
      <geometry name="rh_thproximal_collision_geom">
        <cylinder length="0.018" radius="0.012"/>
      </geometry>
    </collision>
  </link>
  <joint name="rh_THJ4" type="revolute">
    <parent link="rh_thbase"/>
    <child link="rh_thproximal"/>
    <origin rpy="0 0 0" xyz="0 0 0"/>
    <axis xyz="1.0 0 0"/>
    <limit effort="3" lower="0.0" upper="1.2217304764" velocity="4.0"/>
    <dynamics damping="0.2"/>
  </joint>

  <!-- prefix can be anything but usually is "r_" or  "l_" for right and left hands distinction -->
  <gazebo reference="rh_thproximal">
    <selfCollide>false</selfCollide>
  </gazebo>
  <link name="rh_thhub">
    <inertial>
      <mass value="0.005"/>
      <origin rpy="0 0 0" xyz="0 0 0"/>
      <inertia ixx="0.000001" ixy="0.0" ixz="0.0" iyy="0.000001" iyz="0.0" izz="0.0000003"/>
    </inertial>
    <visual>
      <origin rpy="0 0 0" xyz="0 0 0"/>
      <geometry name="rh_thhub_visual">
        <box size="0.001 0.001 0.001"/>
      </geometry>
      <material name="shadow_thhub_material">
        <color rgba="0.7 0.7 0.7 1.0"/>
      </material>
    </visual>
    <collision>
      <origin rpy="0 0 0" xyz="0 0 0"/>
      <geometry name="rh_thhub_collision_geom">
        <sphere radius="0.010"/>
      </geometry>
    </collision>
  </link>
  <joint name="rh_THJ3" type="revolute">
    <parent link="rh_thproximal"/>
    <child link="rh_thhub"/>
    <origin rpy="0 0 0" xyz="0 0 0.038"/>
    <axis xyz="1 0 0"/>
    <limit effort="2.0" lower="-0.209439510239" upper="0.209439510239" velocity="4.0"/>
    <dynamics damping="0.2"/>
  </joint>

  <!-- prefix can be anything but usually is "r_" or  "l_" for right and left hands distinction -->
  <gazebo reference="rh_thhub">
    <selfCollide>true</selfCollide>
  </gazebo>
  <link name="rh_thmiddle">
    <inertial>
      <mass value="0.020"/>
      <origin rpy="0 0 0" xyz="0 0 0.016"/>
      <inertia ixx="0.0000051" ixy="0.0" ixz="0.0" iyy="0.0000051" iyz="0.0" izz="0.00000121"/>
    </inertial>
    <visual>
      <origin rpy="0 0 0" xyz="0 0 0"/>
      <geometry name="rh_thmiddle_visual">
        <mesh filename="package://sr_description/hand/model/TH2_z.dae" scale="0.001 0.001 0.001"/>
      </geometry>
      <material name="shadow_thmiddle_material">
        <color rgba="0.2 0.2 0.2 1.0"/>
      </material>
    </visual>
    <collision>
      <origin rpy="0 0 0" xyz="0 0 0.012"/>
      <geometry name="rh_thmiddle_collision_geom">
        <cylinder length="0.018" radius="0.011"/>
      </geometry>
    </collision>
    <collision>
      <origin rpy="0 0 0" xyz="0 0 0.019"/>
      <geometry>
        <sphere radius="0.011"/>
      </geometry>
    </collision>
  </link>
  <joint name="rh_THJ2" type="revolute">
    <parent link="rh_thhub"/>
    <child link="rh_thmiddle"/>
    <origin rpy="0 0 0" xyz="0 0 0"/>
    <axis xyz="0 -1 0"/>
    <limit effort="2.0" lower="-0.698131700798" upper="0.698131700798" velocity="2.0"/>
    <dynamics damping="0.1"/>
  </joint>

  <!-- prefix can be anything but usually is "r_" or  "l_" for right and left hands distinction -->
  <gazebo reference="rh_thmiddle">
    <selfCollide>true</selfCollide>
  </gazebo>
  <!-- common -->
  <link name="rh_thdistal">
    <inertial>
      <mass value="0.016"/>
      <origin rpy="0 0 0" xyz="0 0 0.01375"/>
      <inertia ixx="0.0000021" ixy="0.0" ixz="0.0" iyy="0.0000022" iyz="0.0" izz="0.000001"/>
    </inertial>
    <visual>
      <origin rpy="0 0 0" xyz="0 0 0"/>
      <geometry name="rh_thdistal_visual">
        <!-- Standard distal  -->
        <mesh filename="package://sr_description/hand/model/TH1_z.dae" scale="0.001 0.001 0.001"/>
      </geometry>
      <material name="shadow_thmiddle_material">
        <color rgba="0.2 0.2 0.2 1.0"/>
      </material>
    </visual>
    <collision>
      <origin rpy="0 0 0" xyz="0 0 0"/>
      <geometry name="rh_thmiddle_collision_geom">
        <!-- Standard distal  -->
        <mesh filename="package://sr_description/hand/model/TH1_z.dae" scale="0.001 0.001 0.001"/>
        <!--      <box size="0.015 0.015 0.015" /> -->
      </geometry>
    </collision>
  </link>
  <joint name="rh_THJ1" type="revolute">
    <parent link="rh_thmiddle"/>
    <child link="rh_thdistal"/>
    <origin rpy="0 0 -1.57079632679" xyz="0 0 0.032"/>
    <axis xyz="1 0 0"/>
    <limit effort="1.0" lower="0" upper="1.57079632679" velocity="4.0"/>
    <dynamics damping="0.2"/>
  </joint>
  <gazebo reference="rh_THJ1">
    <provideFeedback>1</provideFeedback>
    <implicitSpringDamper>1</implicitSpringDamper>
  </gazebo>
  <link name="rh_thtip">
    <inertial>
      <mass value="0.001"/>
      <inertia ixx="0.0" ixy="0.0" ixz="0.0" iyy="0.0" iyz="0.0" izz="0.0"/>
    </inertial>
  </link>
  <joint name="rh_thtip" type="fixed">
    <parent link="rh_thdistal"/>
    <child link="rh_thtip"/>
    <origin rpy="0 0 0" xyz="0 0 0.0275"/>
  </joint>
  <!-- prefix can be anything but usually is "r_" or  "l_" for right and left hands distinction -->
  <gazebo reference="rh_thdistal">
    <mu1 value="500.0"/>
    <mu2 value="500.0"/>
    <kp value="10000000.0"/>
    <kd value="1.0"/>
    <selfCollide>true</selfCollide>
  </gazebo>

</robot>

