
<?xml version="1.0" ?>
<robot name="vizzy_hand"
  xmlns:controller="http://playerstage.sourceforge.net/gazebo/xmlschema/#controller"
  xmlns:interface="http://playerstage.sourceforge.net/gazebo/xmlschema/#interface"
  xmlns:sensor="http://playerstage.sourceforge.net/gazebo/xmlschema/#sensor"
  xmlns:xacro="http://ros.org/wiki/xacro">

  <!-- Root link, on the ground just below the robot origin -->
  <link name="base_footprint">
  </link>

  <!-- Virtual joints for floating behaviour -->
  
  <!-- Virtual link world -->
  <link name="world"/>

  <!-- Translation -->
  <joint name="virtual_px_joint" type="prismatic">
    <origin rpy="0 0 0" xyz="0 0 0"/>
    <axis xyz="1 0 0"/>
    <parent link="world"/>
    <child link="virtual_px_link"/>
    <limit effort="5.0" lower="-0.5" upper="0.5" velocity="5.0"/>
    <dynamics damping="600.0" friction="10.0"/>
  </joint>
  <link name="virtual_px_link">
    <visual>
      <origin rpy="0 0 0.0" xyz="0 0 0"/>
      <geometry>
        <cylinder length="0.01" radius="0.005"/>
      </geometry>
    </visual>
    <inertial>
      <origin rpy="0 0 0" xyz="0.0 0.0 0.0"/>
      <mass value="0.001"/>
      <inertia ixx="0.01" ixy="0" ixz="0" iyy="0.01" iyz="0" izz="0.01"/>
    </inertial>
    <collision>
      <origin rpy="0 0 0" xyz="0.0 0.0 -20.0"/>
      <geometry>
        <cylinder length="0.001" radius="0.005"/>
      </geometry>
    </collision>
  </link>
    <joint name="virtual_py_joint" type="prismatic">
    <origin rpy="0 0 0" xyz="0 0 0"/>
    <axis xyz="0 1 0"/>
    <parent link="virtual_px_link"/>
    <child link="virtual_py_link"/>
    <limit effort="5.0" lower="-0.5" upper="0.5" velocity="5.0"/>
    <dynamics damping="600.0" friction="10.0"/>
  </joint>
  <link name="virtual_py_link">
    <visual>
      <origin rpy="0 0 0.0" xyz="0 0 0"/>
      <geometry>
        <cylinder length="0.01" radius="0.005"/>
      </geometry>
    </visual>
    <inertial>
      <origin rpy="0 0 0" xyz="0.0 0.0 0.0"/>
      <mass value="0.001"/>
      <inertia ixx="0.01" ixy="0" ixz="0" iyy="0.01" iyz="0" izz="0.01"/>
    </inertial>
    <collision>
      <origin rpy="0 0 0" xyz="0.0 0.0 -20.0"/>
      <geometry>
        <cylinder length="0.001" radius="0.005"/>
      </geometry>
    </collision>
  </link>
  <joint name="virtual_pz_joint" type="prismatic">
    <origin rpy="0 0 0" xyz="0 0 0"/>
    <axis xyz="0 0 1"/>
    <parent link="virtual_py_link"/>
    <child link="virtual_pz_link"/>
    <limit effort="20.0" lower="0.0" upper="1.0" velocity="20.0"/>
    <dynamics damping="50.0" friction="0.0"/>
  </joint>
  <link name="virtual_pz_link">
    <visual>
      <origin rpy="0 0 0.0" xyz="0 0 0"/>
      <geometry>
        <cylinder length="0.01" radius="0.005"/>
      </geometry>
    </visual>
    <inertial>
      <origin rpy="0 0 0" xyz="0.0 0.0 0.0"/>
      <mass value="0.001"/>
      <inertia ixx="0.01" ixy="0" ixz="0" iyy="0.01" iyz="0" izz="0.01"/>
    </inertial>
    <collision>
      <origin rpy="0 0 0" xyz="0.0 0.0 -20.0"/>
      <geometry>
        <cylinder length="0.001" radius="0.005"/>
      </geometry>
    </collision>
  </link>

  <!-- Rotation -->
  <joint name="virtual_ry_joint" type="revolute">
    <origin rpy="0 0 0" xyz="0 0 0"/>
    <axis xyz="0 0 1"/>
    <parent link="virtual_pz_link"/>
    <child link="virtual_ry_link"/>
    <limit lower="-1.57" upper="1.57" effort="10.01" velocity="0.0"/>
    <dynamics damping="100000" friction="10.0"/>
  </joint>
  <link name="virtual_ry_link">
    <visual>
      <origin rpy="0 0 0.0" xyz="0 0 0"/>
      <geometry>
        <cylinder length="0.01" radius="0.005"/>
      </geometry>
    </visual>
    <inertial>
      <origin rpy="0 0 0" xyz="0.0 0.0 0.0"/>
      <mass value="0.001"/>
      <inertia ixx="0.01" ixy="0" ixz="0" iyy="0.01" iyz="0" izz="0.01"/>
    </inertial>
    <collision>
      <origin rpy="0 0 0" xyz="0.0 0.0 -20.0"/>
      <geometry>
        <cylinder length="0.001" radius="0.005"/>
      </geometry>
    </collision>
  </link>
    <joint name="virtual_rp_joint" type="revolute">
    <origin rpy="0 0 0" xyz="0 0 0"/>
    <axis xyz="0 1 0"/>
    <parent link="virtual_ry_link"/>
    <child link="virtual_rp_link"/>
    <limit lower="-1.57" upper="1.57" effort="10.01" velocity="0.0"/>
    <dynamics damping="100000" friction="10.0"/>
  </joint>
  <link name="virtual_rp_link">
    <visual>
      <origin rpy="0 0 0.0" xyz="0 0 0"/>
      <geometry>
        <cylinder length="0.01" radius="0.005"/>
      </geometry>
    </visual>
    <inertial>
      <origin rpy="0 0 0" xyz="0.0 0.0 0.0"/>
      <mass value="0.001"/>
      <inertia ixx="0.01" ixy="0" ixz="0" iyy="0.01" iyz="0" izz="0.01"/>
    </inertial>
    <collision>
      <origin rpy="0 0 0" xyz="0.0 0.0 -20.0"/>
      <geometry>
        <cylinder length="0.001" radius="0.005"/>
      </geometry>
    </collision>
  </link>
    <joint name="virtual_rr_joint" type="revolute">
    <origin rpy="0 0 0" xyz="0 0 0"/>
    <axis xyz="1 0 0"/>
    <parent link="virtual_rp_link"/>
    <child link="base_footprint"/>
    <limit lower="-1.57" upper="1.57" effort="10.01" velocity="0.0"/>
    <dynamics damping="100000" friction="10.0"/>
  </joint>

  <!-- Gazebo gripper plugin -->
  <gazebo>
    <plugin name="hand_plugin" filename="libHandPlugin.so">
      <!-- Reference names -->
      <model>vizzy_right_hand</model>
      <!-- Fingers -->
      <actuatedJoint name="r_thumb_phal_1_joint">
        <mimicJoint name="r_thumb_phal_2_joint" multiplier="0.5" />
        <mimicJoint name="r_thumb_phal_3_joint" multiplier="0.5" />
      </actuatedJoint>
      <actuatedJoint name="r_ind_phal_1_joint">
        <mimicJoint name="r_ind_phal_2_joint" multiplier="0.5" />
        <mimicJoint name="r_ind_phal_3_joint" multiplier="0.5" />
      </actuatedJoint>
      <!-- Vizzy's med and min fingers are coupled and act as one -->
      <actuatedJoint name="r_med_phal_1_joint">
        <mimicJoint name="r_med_phal_2_joint" multiplier="0.5" />
        <mimicJoint name="r_med_phal_3_joint" multiplier="0.5" />
        <mimicJoint name="r_min_phal_1_joint" multiplier="0.5" />
        <mimicJoint name="r_min_phal_3_joint" multiplier="0.5" />
        <mimicJoint name="r_min_phal_2_joint" multiplier="0.5" />
      </actuatedJoint>
      <!-- Virtual joints for floating behaviour -->
      <virtualJoints>
        virtual_px_joint virtual_py_joint virtual_pz_joint
        virtual_rr_joint virtual_rp_joint virtual_ry_joint
      </virtualJoints>
      <!-- Constraints -->
      <gravity>0</gravity>
    </plugin>
  </gazebo>

  <!-- Vizzy's right hand -->
  <joint name="r_hand_base_joint_fix" type="fixed">
    <origin rpy="1.570796 0 0" xyz="0.007 -0.076 0.009"/>
    <parent link="base_footprint"/>
    <child link="r_hand_base_link"/>
    <axis xyz="0 0 0"/>
  </joint>
  <link name="r_hand_base_link">
    <inertial>
      <origin rpy="0 0 0" xyz="-0.00674438981790416 -0.0058664849056831 0.00390957326685741"/>
      <mass value="0.151046667629674"/>
      <inertia ixx="0.000146470764076254" ixy="-1.43291885346107E-06" ixz="-2.07342162004204E-05" iyy="0.000224213192446366" iyz="-2.70250573740841E-06" izz="9.93519001771392E-05"/>
    </inertial>
    <visual>
      <origin rpy="0 0 0" xyz="0 0 0"/>
      <geometry>
        <mesh filename="package://vizzy_description/meshes/hand/r_hand_base_link.STL"/>
      </geometry>
      <material name="">
        <color rgba="0.796078431372549 0.823529411764706 0.937254901960784 1"/>
      </material>
    </visual>
    <collision>
      <origin rpy="0 0 0" xyz="-0.008 -0.0134 0"/>
      <geometry>
        <box size="0.090 0.030 0.0900"/>
      </geometry>
    </collision>
  </link>
  <link name="r_min_phal_1_link">
    <inertial>
      <origin rpy="0 0 0" xyz="-0.0065863332980695 0.000338633799509286 0.0178212692703573"/>
      <mass value="0.0123116066856987"/>
      <inertia ixx="1.31758404800717E-06" ixy="-3.84070099097907E-10" ixz="-1.27867316658086E-10" iyy="1.33241779844217E-06" iyz="-8.28056937395449E-09" izz="4.19810828425124E-07"/>
    </inertial>
    <visual>
      <origin rpy="0 0 0" xyz="0 0 0"/>
      <geometry>
        <mesh filename="package://vizzy_description/meshes/hand/r_min_phal_1_link.STL"/>
      </geometry>
      <material name="">
        <color rgba="0.898039215686275 0.917647058823529 0.929411764705882 1"/>
      </material>
    </visual>
    <collision>
      <origin rpy="0 0 0" xyz="-0.0068 0 0.0177"/>
      <geometry>
        <box size="0.0136 0.0136 0.0445"/>
      </geometry>
    </collision>
  </link>
  <joint name="r_min_phal_1_joint" type="revolute">
    <origin rpy="6.21748940377807E-17 -0.174532925199439 3.14159265358979" xyz="0.0206022740439909 -0.00583604310721738 0.0444337137891329"/>
    <parent link="r_hand_base_link"/>
    <child link="r_min_phal_1_link"/>
    <axis xyz="1 0 0"/>
    <limit effort="0" lower="0" upper="1.57" velocity="0"/>
  </joint>
  <link name="r_min_phal_1_link_fix">
    <inertial>
      <origin rpy="0 0 0" xyz="-0.00172879723518117 0.00767822711194731 0.00062912481037776"/>
      <mass value="0.00282550462257503"/>
      <inertia ixx="2.01497129990919E-07" ixy="2.16240614332509E-08" ixz="5.94116205047544E-08" iyy="1.72890117193847E-07" iyz="-2.30807929346575E-08" izz="1.17876895053349E-07"/>
    </inertial>
    <visual>
      <origin rpy="0 0 0" xyz="0 0 0"/>
      <geometry>
        <mesh filename="package://vizzy_description/meshes/hand/r_min_phal_1_link_fix.STL"/>
      </geometry>
      <material name="">
        <color rgba="0.776470588235294 0.756862745098039 0.737254901960784 1"/>
      </material>
    </visual>
    <collision>
      <origin rpy="-3.1416 -1.2217 1.5708" xyz="-0.009 0.01200 0.01300"/>
      <geometry>
        <box size="0.015 0.0045 0.011"/>
      </geometry>
    </collision>
  </link>
  <joint name="r_min_phal_1_joint_fix" type="fixed">
    <origin rpy="-2.79252680319092 -2.96655185942005E-17 1.5707963267949" xyz="-0.0135778483455014 0 0.033"/>
    <parent link="r_min_phal_1_link"/>
    <child link="r_min_phal_1_link_fix"/>
    <axis xyz="0 0 0"/>
  </joint>
  <link name="r_min_phal_2_link">
    <inertial>
      <origin rpy="0 0 0" xyz="-0.0146794976295984 0.000321778454853602 -1.60585011899778E-05"/>
      <mass value="0.00935905263397591"/>
      <inertia ixx="3.25448973931958E-07" ixy="7.6792767696661E-09" ixz="2.91914436315786E-10" iyy="7.82460629612251E-07" iyz="-5.74854295945315E-10" izz="7.70225783044348E-07"/>
    </inertial>
    <visual>
      <origin rpy="0 0 0" xyz="0 0 0"/>
      <geometry>
        <mesh filename="package://vizzy_description/meshes/hand/r_min_phal_2_link.STL"/>
      </geometry>
      <material name="">
        <color rgba="0.898039215686275 0.917647058823529 0.929411764705882 1"/>
      </material>
    </visual>
    <collision>
      <origin rpy="0 0 0" xyz="-0.0145 0 0"/>
      <geometry>
        <box size="0.0380 0.0136 0.0136"/>
      </geometry>
    </collision>
  </link>
  <joint name="r_min_phal_2_joint" type="revolute">
    <origin rpy="0.390965355013273 1.57079631189374 0.404891786285083" xyz="-0.00657784834550136 0 0.0330000000000001"/>
    <parent link="r_min_phal_1_link"/>
    <child link="r_min_phal_2_link"/>
    <axis xyz="0 0 1"/>
    <limit effort="0" lower="0" upper="1.57" velocity="0"/>
  </joint>
  <link name="r_min_phal_2_link_fix">
    <inertial>
      <origin rpy="0 0 0" xyz="0.00103349935688929 0.00697346811741156 -0.0017476111791478"/>
      <mass value="0.00257761474790775"/>
      <inertia ixx="1.23080849742913E-07" ixy="4.8733648423492E-10" ixz="3.10924773578245E-08" iyy="9.04329465453797E-08" iyz="2.75926783373023E-11" izz="9.21929606188827E-08"/>
    </inertial>
    <visual>
      <origin rpy="0 0 0" xyz="0 0 0"/>
      <geometry>
        <mesh filename="package://vizzy_description/meshes/hand/r_min_phal_2_link_fix.STL"/>
      </geometry>
      <material name="">
        <color rgba="0.776470588235294 0.756862745098039 0.737254901960784 1"/>
      </material>
    </visual>
    <collision>
      <origin rpy="3.1416 1.5551 -1.5708" xyz="0.009 0.0067 -0.0136"/>
      <geometry>
        <box size="0.008 0.0045 0.011"/>
      </geometry>
    </collision>
  </link>
  <joint name="r_min_phal_2_joint_fix" type="fixed">
    <origin rpy="1.58646881860206 -4.3102798399879E-10 -1.57079634168982" xyz="-0.0265 0 -0.00699999999999999"/>
    <parent link="r_min_phal_2_link"/>
    <child link="r_min_phal_2_link_fix"/>
    <axis xyz="0 0 0"/>
  </joint>
  <link name="r_min_phal_3_link">
    <inertial>
      <origin rpy="0 0 0" xyz="-0.0125548646076213 0.000562521411253319 -1.90458985400606E-05"/>
      <mass value="0.00838713757871327"/>
      <inertia ixx="2.605055677365E-07" ixy="2.79008592685349E-08" ixz="-1.74761643269195E-10" iyy="4.40992543732786E-07" iyz="-6.25455793840396E-10" izz="4.4547901908355E-07"/>
    </inertial>
    <visual>
      <origin rpy="0 0 0" xyz="0 0 0"/>
      <geometry>
        <mesh filename="package://vizzy_description/meshes/hand/r_min_phal_3_link.STL"/>
      </geometry>
      <material name="">
        <color rgba="0.898039215686275 0.917647058823529 0.929411764705882 1"/>
      </material>
    </visual>
    <collision>
      <origin rpy="0 0 0" xyz="-0.010 0 0"/>
      <geometry>
        <box size="0.029 0.0136 0.0136"/>
      </geometry>
    </collision>
  </link>
  <joint name="r_min_phal_3_joint" type="revolute">
    <origin rpy="-2.72852300466093E-16 -1.38777878078145E-16 1.38777878078145E-16" xyz="-0.0265 0 0"/>
    <parent link="r_min_phal_2_link"/>
    <child link="r_min_phal_3_link"/>
    <axis xyz="0 0 1"/>
    <limit effort="0" lower="0" upper="1.57" velocity="0"/>
  </joint>
  <link name="r_min_phal_3_link_fix">
    <inertial>
      <origin rpy="0 0 0" xyz="0.00766697975732301 -0.00206053521596643 -2.63862865584885E-10"/>
      <mass value="0.000998337750354604"/>
      <inertia ixx="2.82919940857841E-08" ixy="1.55555318454921E-08" ixz="7.05332250168016E-14" iyy="3.53807305854586E-08" iyz="-6.32381362699079E-14" izz="4.58877792771015E-08"/>
    </inertial>
    <visual>
      <origin rpy="0 0 0" xyz="0 0 0"/>
      <geometry>
        <mesh filename="package://vizzy_description/meshes/hand/r_min_phal_3_link_fix.STL"/>
      </geometry>
      <material name="">
        <color rgba="0.776470588235294 0.756862745098039 0.737254901960784 1"/>
      </material>
    </visual>
    <collision>
      <origin rpy="0 0 0" xyz="0.003 0.0022 0"/>
      <geometry>
        <box size="0.012 0.0045 0.011"/>
      </geometry>
    </collision>
  </link>
  <joint name="r_min_phal_3_joint_fix" type="fixed">
    <origin rpy="-3.8200656685833E-16 -4.71844785465692E-16 3.14159265358979" xyz="-0.0129350000000001 -0.00700000000000108 0"/>
    <parent link="r_min_phal_3_link"/>
    <child link="r_min_phal_3_link_fix"/>
    <axis xyz="0 0 0"/>
  </joint>
  <link name="r_med_phal_1_link">
    <inertial>
      <origin rpy="0 0 0" xyz="0.00290827999991534 0.000338633831535875 0.0178212708626085"/>
      <mass value="0.0123116051705352"/>
      <inertia ixx="1.31758380807131E-06" ixy="-3.84058346750519E-10" ixz="-1.27794118562984E-10" iyy="1.33241758331684E-06" iyz="-8.28056765730366E-09" izz="4.19810810233747E-07"/>
    </inertial>
    <visual>
      <origin rpy="0 0 0" xyz="0 0 0"/>
      <geometry>
        <mesh filename="package://vizzy_description/meshes/hand/r_med_phal_1_link.STL"/>
      </geometry>
      <material name="">
        <color rgba="0.898039215686275 0.917647058823529 0.929411764705882 1"/>
      </material>
    </visual>
    <collision>
      <origin rpy="0 0 0" xyz="0.0032 0 0.0177"/>
      <geometry>
        <box size="0.0136 0.0136 0.0445"/>
      </geometry>
    </collision>
  </link>
  <joint name="r_med_phal_1_joint" type="revolute">
    <origin rpy="6.12303176911189E-17 4.59123512130311E-49 3.14159265358979" xyz="0 -0.00583604310721694 0.0501388217403881"/>
    <parent link="r_hand_base_link"/>
    <child link="r_med_phal_1_link"/>
    <axis xyz="1 0 0"/>
    <limit effort="0" lower="0" upper="1.57" velocity="0"/>
  </joint>
  <link name="r_med_phal_1_link_fix">
    <inertial>
      <origin rpy="0 0 0" xyz="0.00172879723518201 -0.00699999999999988 0.00321729227918073"/>
      <mass value="0.00282550462257504"/>
      <inertia ixx="2.01497129990919E-07" ixy="3.6572808233828E-21" ixz="-6.32245259679356E-08" iyy="1.81290840403138E-07" iyz="4.38994985426098E-15" izz="1.09476171844062E-07"/>
    </inertial>
    <visual>
      <origin rpy="0 0 0" xyz="0 0 0"/>
      <geometry>
        <mesh filename="package://vizzy_description/meshes/hand/r_med_phal_1_link_fix.STL"/>
      </geometry>
      <material name="">
        <color rgba="0.776470588235294 0.756862745098039 0.737254901960784 1"/>
      </material>
    </visual>
    <collision>
      <origin rpy="0 0 0" xyz="0.009 -0.007 0.01620"/>
      <geometry>
        <box size="0.0045 0.011 0.015"/>
      </geometry>
    </collision>
  </link>
  <joint name="r_med_phal_1_joint_fix" type="fixed">
    <origin rpy="3.14159265358979 0 -1.5707963267949" xyz="-0.00408323604951738 0 0.033"/>
    <parent link="r_med_phal_1_link"/>
    <child link="r_med_phal_1_link_fix"/>
    <axis xyz="0 0 0"/>
  </joint>
  <link name="r_med_phal_2_link">
    <inertial>
      <origin rpy="0 0 0" xyz="-0.0146795000576953 0.000321778664566535 -1.60575358664678E-05"/>
      <mass value="0.00935905088241304"/>
      <inertia ixx="3.25448959273416E-07" ixy="7.67926075575246E-09" ixz="2.91863003805068E-10" iyy="7.82460450623358E-07" iyz="-5.74844656431952E-10" izz="7.70225580712677E-07"/>
    </inertial>
    <visual>
      <origin rpy="0 0 0" xyz="0 0 0"/>
      <geometry>
        <mesh filename="package://vizzy_description/meshes/hand/r_med_phal_2_link.STL"/>
      </geometry>
      <material name="">
        <color rgba="0.898039215686275 0.917647058823529 0.929411764705882 1"/>
      </material>
    </visual>
    <collision>
      <origin rpy="0 0 0" xyz="-0.0145 0 0"/>
      <geometry>
        <box size="0.0380 0.0136 0.0136"/>
      </geometry>
    </collision>
  </link>
  <joint name="r_med_phal_2_joint" type="revolute">
    <origin rpy="0 1.5707963267949 0" xyz="0.00291676395048262 0 0.0329999999999999"/>
    <parent link="r_med_phal_1_link"/>
    <child link="r_med_phal_2_link"/>
    <axis xyz="0 0 1"/>
    <limit effort="0" lower="0" upper="1.57" velocity="0"/>
  </joint>
  <link name="r_med_phal_2_link_fix">
    <inertial>
      <origin rpy="0 0 0" xyz="0.0118618906099282 -0.00596650062172868 -3.51281503885303E-17"/>
      <mass value="0.00257761474790776"/>
      <inertia ixx="9.21933940240845E-08" ixy="3.10962967844786E-08" ixz="-1.51647359708518E-16" iyy="1.2308084881656E-07" iyz="-2.51381984882185E-21" izz="9.04325140665307E-08"/>
    </inertial>
    <visual>
      <origin rpy="0 0 0" xyz="0 0 0"/>
      <geometry>
        <mesh filename="package://vizzy_description/meshes/hand/r_med_phal_2_link_fix.STL"/>
      </geometry>
      <material name="">
        <color rgba="0.776470588235294 0.756862745098039 0.737254901960784 1"/>
      </material>
    </visual>
    <collision>
      <origin rpy="0 0 0" xyz="0 0.00225 0"/>
      <geometry>
        <box size="0.008 0.0045 0.011"/>
      </geometry>
    </collision>
  </link>
  <joint name="r_med_phal_2_joint_fix" type="fixed">
    <origin rpy="1.04622193607335E-16 5.37764277552811E-17 -3.14159265358979" xyz="-0.0130000000000001 -0.00700000000000047 0"/>
    <parent link="r_med_phal_2_link"/>
    <child link="r_med_phal_2_link_fix"/>
    <axis xyz="0 0 0"/>
  </joint>
  <link name="r_med_phal_3_link">
    <inertial>
      <origin rpy="0 0 0" xyz="-0.012554865901244 0.000562521495778251 -1.90455588882201E-05"/>
      <mass value="0.00838713661986732"/>
      <inertia ixx="2.6050555476848E-07" ixy="2.79008518020934E-08" ixz="-1.74801618678074E-10" iyy="4.40992441430365E-07" iyz="-6.25441468356934E-10" izz="4.45478908833012E-07"/>
    </inertial>
    <visual>
      <origin rpy="0 0 0" xyz="0 0 0"/>
      <geometry>
        <mesh filename="package://vizzy_description/meshes/hand/r_med_phal_3_link.STL"/>
      </geometry>
      <material name="">
        <color rgba="0.898039215686275 0.917647058823529 0.929411764705882 1"/>
      </material>
    </visual>
    <collision>
      <origin rpy="0 0 0" xyz="-0.010 0 0"/>
      <geometry>
        <box size="0.029 0.0136 0.0136"/>
      </geometry>
    </collision>
  </link>
  <joint name="r_med_phal_3_joint" type="revolute">
    <origin rpy="9.12073853905443E-17 -2.22044604925031E-16 2.20744161709213E-32" xyz="-0.0265 0 0"/>
    <parent link="r_med_phal_2_link"/>
    <child link="r_med_phal_3_link"/>
    <axis xyz="0 0 1"/>
    <limit effort="0" lower="0" upper="1.57" velocity="0"/>
  </joint>
  <link name="r_med_phal_3_link_fix">
    <inertial>
      <origin rpy="0 0 0" xyz="0.007667 -0.0020605 4.3413E-10"/>
      <mass value="0.00099834"/>
      <inertia ixx="2.8539E-08" ixy="1.5556E-08" ixz="6.8151E-14" iyy="3.5628E-08" iyz="-6.5145E-14" izz="4.5888E-08"/>
    </inertial>
    <visual>
      <origin rpy="0 0 0" xyz="0 0 0"/>
      <geometry>
        <mesh filename="package://vizzy_description/meshes/hand/r_med_phal_3_link_fix.STL"/>
      </geometry>
      <material name="">
        <color rgba="0.776470588235294 0.756862745098039 0.737254901960784 1"/>
      </material>
    </visual>
    <collision>
      <origin rpy="0 0 0" xyz="0.003 0.0022 0"/>
      <geometry>
        <box size="0.012 0.0045 0.011"/>
      </geometry>
    </collision>
  </link>
  <joint name="r_med_phal_3_joint_fix" type="fixed">
    <origin rpy="-2.10108554992216E-17 2.65412691824451E-16 3.14159265358979" xyz="-0.0129350000000001 -0.00700000000000102 0"/>
    <parent link="r_med_phal_3_link"/>
    <child link="r_med_phal_3_link_fix"/>
    <axis xyz="0 0 0"/>
  </joint>
  <link name="r_ind_phal_1_link">
    <inertial>
      <origin rpy="0 0 0" xyz="0.014601465068958 0.00033863337883044 0.01782127079059"/>
      <mass value="0.0123116032374656"/>
      <inertia ixx="1.31758383563722E-06" ixy="-3.84048264805816E-10" ixz="-1.27740583343447E-10" iyy="1.3324175993775E-06" iyz="-8.2806058248575E-09" izz="4.19810810567381E-07"/>
    </inertial>
    <visual>
      <origin rpy="0 0 0" xyz="0 0 0"/>
      <geometry>
        <mesh filename="package://vizzy_description/meshes/hand/r_ind_phal_1_link.STL"/>
      </geometry>
      <material name="">
        <color rgba="0.898039215686275 0.917647058823529 0.929411764705882 1"/>
      </material>
    </visual>
    <collision>
      <origin rpy="0 0 0" xyz="0.0148 0 0.0177"/>
      <geometry>
        <box size="0.0136 0.0136 0.0445"/>
      </geometry>
    </collision>
  </link>
  <joint name="r_ind_phal_1_joint" type="revolute">
    <origin rpy="6.21748940377809E-17 0.174532925199461 -3.14159265358979" xyz="-0.0175257277459651 -0.00583604310721693 0.0479445755984035"/>
    <parent link="r_hand_base_link"/>
    <child link="r_ind_phal_1_link"/>
    <axis xyz="1 0 0"/>
    <limit effort="0" lower="0" upper="1.57" velocity="0"/>
  </joint>
  <link name="r_ind_phal_1_link_fix">
    <inertial>
      <origin rpy="0 0 0" xyz="-0.00172879723518099 0.00547746957905512 0.00541740681693755"/>
      <mass value="0.00282550462257504"/>
      <inertia ixx="2.0149712999092E-07" ixy="-2.16240614332544E-08" ixz="5.94116205047534E-08" iyy="1.72890122837457E-07" iyz="2.30807862088658E-08" izz="1.1787688940974E-07"/>
    </inertial>
    <visual>
      <origin rpy="0 0 0" xyz="0 0 0"/>
      <geometry>
        <mesh filename="package://vizzy_description/meshes/hand/r_ind_phal_1_link_fix.STL"/>
      </geometry>
      <material name="">
        <color rgba="0.776470588235294 0.756862745098039 0.737254901960784 1"/>
      </material>
    </visual>
    <collision>
      <origin rpy="0 -1.2217 -1.5708" xyz="-0.009 0.001 0.01785"/>
      <geometry>
        <box size="0.015 0.0045 0.011"/>
      </geometry>
    </collision>
  </link>
  <joint name="r_ind_phal_1_joint_fix" type="fixed">
    <origin rpy="2.79252680319087 2.96655185942041E-17 1.5707963267949" xyz="0.00760994818899727 0 0.0330000000000009"/>
    <parent link="r_ind_phal_1_link"/>
    <child link="r_ind_phal_1_link_fix"/>
    <axis xyz="0 0 0"/>
  </joint>
  <link name="r_ind_phal_2_link">
    <inertial>
      <origin rpy="0 0 0" xyz="-0.0146795003248846 0.000321778719691425 -1.60569463318154E-05"/>
      <mass value="0.00935904736941849"/>
      <inertia ixx="3.25448942816778E-07" ixy="7.67927393287092E-09" ixz="2.91829328071E-10" iyy="7.82460460014294E-07" iyz="-5.74841846680158E-10" izz="7.70225589038739E-07"/>
    </inertial>
    <visual>
      <origin rpy="0 0 0" xyz="0 0 0"/>
      <geometry>
        <mesh filename="package://vizzy_description/meshes/hand/r_ind_phal_2_link.STL"/>
      </geometry>
      <material name="">
        <color rgba="0.898039215686275 0.917647058823529 0.929411764705882 1"/>
      </material>
    </visual>
    <collision>
      <origin rpy="0 0 0" xyz="-0.0145 0 0"/>
      <geometry>
        <box size="0.0380 0.0136 0.0136"/>
      </geometry>
    </collision>
  </link>
  <joint name="r_ind_phal_2_joint" type="revolute">
    <origin rpy="2.1073424255447E-08 1.5707963267949 0" xyz="0.0146099481889973 0 0.0330000000000009"/>
    <parent link="r_ind_phal_1_link"/>
    <child link="r_ind_phal_2_link"/>
    <axis xyz="0 0 1"/>
    <limit effort="0" lower="0" upper="1.57" velocity="0"/>
  </joint>
  <link name="r_ind_phal_2_link_fix">
    <inertial>
      <origin rpy="0 0 0" xyz="0.0118618906099284 -0.00596650062172827 -2.08166817117217E-17"/>
      <mass value="0.00257761474790776"/>
      <inertia ixx="9.21933940240852E-08" ixy="3.10962967844789E-08" ixz="-1.51647519662075E-16" iyy="1.2308084881656E-07" iyz="-4.16568156481705E-21" izz="9.0432514066531E-08"/>
    </inertial>
    <visual>
      <origin rpy="0 0 0" xyz="0 0 0"/>
      <geometry>
        <mesh filename="package://vizzy_description/meshes/hand/r_ind_phal_2_link_fix.STL"/>
      </geometry>
      <material name="">
        <color rgba="0.776470588235294 0.756862745098039 0.737254901960784 1"/>
      </material>
    </visual>
    <collision>
      <origin rpy="0 0 0" xyz="0 0.00225 0"/>
      <geometry>
        <box size="0.008 0.0045 0.011"/>
      </geometry>
    </collision>
  </link>
  <joint name="r_ind_phal_2_joint_fix" type="fixed">
    <origin rpy="-5.66815834993211E-17 -4.71844785465692E-16 -3.14159265358979" xyz="-0.013 -0.00699999999999998 0"/>
    <parent link="r_ind_phal_2_link"/>
    <child link="r_ind_phal_2_link_fix"/>
    <axis xyz="0 0 0"/>
  </joint>
  <link name="r_ind_phal_3_link">
    <inertial>
      <origin rpy="0 0 0" xyz="-0.012554864593053 0.000562522193847185 -1.90456569425027E-05"/>
      <mass value="0.00838713389782705"/>
      <inertia ixx="2.60505527476575E-07" ixy="2.79009123592799E-08" ixz="-1.74839156347256E-10" iyy="4.40992467798345E-07" iyz="-6.254340723155E-10" izz="4.45478930576091E-07"/>
    </inertial>
    <visual>
      <origin rpy="0 0 0" xyz="0 0 0"/>
      <geometry>
        <mesh filename="package://vizzy_description/meshes/hand/r_ind_phal_3_link.STL"/>
      </geometry>
      <material name="">
        <color rgba="0.898039215686275 0.917647058823529 0.929411764705882 1"/>
      </material>
    </visual>
    <collision>
      <origin rpy="0 0 0" xyz="-0.010 0 0"/>
      <geometry>
        <box size="0.029 0.0136 0.0136"/>
      </geometry>
    </collision>
  </link>
  <joint name="r_ind_phal_3_joint" type="revolute">
    <origin rpy="-1.28841895152226E-16 -1.94289029309402E-16 2.3823321606963E-16" xyz="-0.0265 0 0"/>
    <parent link="r_ind_phal_2_link"/>
    <child link="r_ind_phal_3_link"/>
    <axis xyz="0 0 1"/>
    <limit effort="0" lower="0" upper="1.57" velocity="0"/>
  </joint>
  <link name="r_ind_phal_3_link_fix">
    <inertial>
      <origin rpy="0 0 0" xyz="0.00766697974840547 -0.00206053520748253 1.5630878397177E-09"/>
      <mass value="0.000998337750144563"/>
      <inertia ixx="2.82350908044463E-08" ixy="1.55555318482283E-08" ixz="6.68066918954923E-14" iyy="3.53238274449731E-08" iyz="-6.21765206842559E-14" izz="4.58877793864804E-08"/>
    </inertial>
    <visual>
      <origin rpy="0 0 0" xyz="0 0 0"/>
      <geometry>
        <mesh filename="package://vizzy_description/meshes/hand/r_ind_phal_3_link_fix.STL"/>
      </geometry>
      <material name="">
        <color rgba="0.776470588235294 0.756862745098039 0.737254901960784 1"/>
      </material>
    </visual>
    <collision>
      <origin rpy="0 0 0" xyz="0.003 0.0022 0"/>
      <geometry>
        <box size="0.012 0.0045 0.011"/>
      </geometry>
    </collision>
  </link>
  <joint name="r_ind_phal_3_joint_fix" type="fixed">
    <origin rpy="-1.85523478651547E-16 -6.38378239159465E-16 3.14159265358979" xyz="-0.0129349999999999 -0.00699999999999999 0"/>
    <parent link="r_ind_phal_3_link"/>
    <child link="r_ind_phal_3_link_fix"/>
    <axis xyz="0 0 0"/>
  </joint>
  <link name="r_thumb_phal_1_link">
    <inertial>
      <origin rpy="0 0 0" xyz="-0.00627940633196825 8.37968861928592E-05 7.22744895452765E-05"/>
      <mass value="0.00234087705696458"/>
      <inertia ixx="6.42086690069036E-08" ixy="-9.16757722375959E-10" ixz="6.88811649213746E-10" iyy="5.92649073898388E-08" iyz="6.66151305801992E-10" izz="7.04099770735271E-08"/>
    </inertial>
    <visual>
      <origin rpy="0 0 0" xyz="0 0 0"/>
      <geometry>
        <mesh filename="package://vizzy_description/meshes/hand/r_thumb_phal_1_link.STL"/>
      </geometry>
      <material name="">
        <color rgba="0.898039215686275 0.917647058823529 0.929411764705882 1"/>
      </material>
    </visual>
    <collision>
      <origin rpy="0 0 0" xyz="-0.00326 0 0"/>
      <geometry>
        <box size="0.01551 0.0136 0.0136"/>
      </geometry>
    </collision>
  </link>
  <joint name="r_thumb_phal_1_joint" type="revolute">
    <origin rpy="3.0577 0.30311 -0.27462" xyz="-0.043854 -0.005836 -0.020232"/>
    <parent link="r_hand_base_link"/>
    <child link="r_thumb_phal_1_link"/>
    <axis xyz="0 0 1"/>
    <limit effort="0" lower="0" upper="1.57" velocity="0"/>
  </joint>
  <link name="r_thumb_phal_1_link_fix">
    <inertial>
      <origin rpy="0 0 0" xyz="1.46236156433506E-05 0.000373790073961183 0.00197982204483294"/>
      <mass value="0.00643378339237506"/>
      <inertia ixx="2.37679766673026E-07" ixy="9.97524325572656E-11" ixz="6.13755121015018E-10" iyy="3.17726875576977E-07" iyz="6.09062370770399E-09" izz="2.34558855671874E-07"/>
    </inertial>
    <visual>
      <origin rpy="0 0 0" xyz="0 0 0"/>
      <geometry>
        <mesh filename="package://vizzy_description/meshes/hand/r_thumb_phal_1_link_fix.STL"/>
      </geometry>
      <material name="">
        <color rgba="0.898039215686275 0.917647058823529 0.929411764705882 1"/>
      </material>
    </visual>
    <collision>
      <origin rpy="0 1.570796 0" xyz="0 0 0.003"/>
      <geometry>
        <box size="0.01852 0.0136 0.0136"/>
      </geometry>
    </collision>
  </link>
  <joint name="r_thumb_phal_1_joint_fix" type="fixed">
    <origin rpy="1.5707963267949 -3.17649272361905E-16 -1.5707963267949" xyz="-0.0175000000000012 0 0"/>
    <parent link="r_thumb_phal_1_link"/>
    <child link="r_thumb_phal_1_link_fix"/>
    <axis xyz="0 0 0"/>
  </joint>
  <link name="r_thumb_phal_2_link">
    <inertial>
      <origin rpy="0 0 0" xyz="-8.48294030898929E-06 0.000338633445444513 0.0178212712750259"/>
      <mass value="0.0123116014240311"/>
      <inertia ixx="1.31758378214817E-06" ixy="-3.84041886468586E-10" ixz="-1.27735483600304E-10" iyy="1.33241755564903E-06" iyz="-8.28057330562904E-09" izz="4.19810804750257E-07"/>
    </inertial>
    <visual>
      <origin rpy="0 0 0" xyz="0 0 0"/>
      <geometry>
        <mesh filename="package://vizzy_description/meshes/hand/r_thumb_phal_2_link.STL"/>
      </geometry>
      <material name="">
        <color rgba="0.898039215686275 0.917647058823529 0.929411764705882 1"/>
      </material>
    </visual>
    <collision>
      <origin rpy="0 0 0" xyz="0 0 0.01775"/>
      <geometry>
        <box size="0.0136 0.0136 0.0445"/>
      </geometry>
    </collision>
  </link>
  <joint name="r_thumb_phal_2_joint" type="revolute">
    <origin rpy="1.5661 -4.703E-16 -1.5708" xyz="-0.0225 0 0"/>
    <parent link="r_thumb_phal_1_link"/>
    <child link="r_thumb_phal_2_link"/>
    <axis xyz="1 0 0"/>
    <limit effort="0" lower="0" upper="1.57" velocity="0"/>
  </joint>
  <link name="r_thumb_phal_2_link_fix">
    <inertial>
      <origin rpy="0 0 0" xyz="-0.0130448715272194 -0.0052712081124219 -4.39738974400417E-11"/>
      <mass value="0.00282550279070484"/>
      <inertia ixx="1.09476043021587E-07" ixy="-6.29793661939661E-08" ixz="5.62433595650017E-15" iyy="2.0059891046147E-07" iyz="1.31722484108464E-16" izz="1.80392567692399E-07"/>
    </inertial>
    <visual>
      <origin rpy="0 0 0" xyz="0 0 0"/>
      <geometry>
        <mesh filename="package://vizzy_description/meshes/hand/r_thumb_phal_2_link_fix.STL"/>
      </geometry>
      <material name="">
        <color rgba="0.776470588235294 0.756862745098039 0.737254901960784 1"/>
      </material>
    </visual>
    <collision>
      <origin rpy="0 0 0" xyz="0 0.0022 0"/>
      <geometry>
        <box size="0.015 0.0045 0.011"/>
      </geometry>
    </collision>
  </link>
  <joint name="r_thumb_phal_2_joint_fix" type="fixed">
    <origin rpy="3.14159265358979 1.5707963267949 0" xyz="0 -0.00700000000000046 0.0167500000000015"/>
    <parent link="r_thumb_phal_2_link"/>
    <child link="r_thumb_phal_2_link_fix"/>
    <axis xyz="0 0 0"/>
  </joint>
  <joint name="r_thumb_phal_3_joint" type="revolute">
    <origin rpy="0 1.5708 0" xyz="0 0 0.033"/>
    <parent link="r_thumb_phal_2_link"/>
    <child link="r_thumb_phal_3_link"/>
    <axis xyz="0 0 1"/>
    <limit effort="0" lower="0" upper="1.57" velocity="0"/>
  </joint>
  <link name="r_thumb_phal_3_link">
    <inertial>
      <origin rpy="0 0 0" xyz="-0.012555 0.00056252 -1.9046E-05"/>
      <mass value="0.0083871"/>
      <inertia ixx="2.6051E-07" ixy="2.7901E-08" ixz="-1.7483E-10" iyy="4.4099E-07" iyz="-6.2543E-10" izz="4.4548E-07"/>
    </inertial>
    <visual>
      <origin rpy="0 0 0" xyz="0 0 0"/>
      <geometry>
        <mesh filename="package://vizzy_description/meshes/hand/r_thumb_phal_3_link.STL"/>
      </geometry>
      <material name="">
        <color rgba="0.89804 0.91765 0.92941 1"/>
      </material>
    </visual>
    <collision>
      <origin rpy="0 0 0" xyz="-0.010 0 0"/>
      <geometry>
        <box size="0.029 0.0136 0.0136"/>
      </geometry>
    </collision>
  </link>
  <link name="r_thumb_phal_3_link_fix">
    <inertial>
      <origin rpy="0 0 0" xyz="0.007667 -0.0020605 1.9636E-09"/>
      <mass value="0.00099834"/>
      <inertia ixx="2.8242E-08" ixy="1.5556E-08" ixz="6.7031E-14" iyy="3.5331E-08" iyz="-6.3214E-14" izz="4.5888E-08"/>
    </inertial>
    <visual>
      <origin rpy="0 0 0" xyz="0 0 0"/>
      <geometry>
        <mesh filename="package://vizzy_description/meshes/hand/r_thumb_phal_3_link_fix.STL"/>
      </geometry>
      <material name="">
        <color rgba="0.776470588235294 0.756862745098039 0.737254901960784 1"/>
      </material>
    </visual>
    <collision>
      <origin rpy="0 0 0" xyz="0.003 0.0022 0"/>
      <geometry>
        <box size="0.012 0.0045 0.011"/>
      </geometry>
    </collision>
  </link>
  <joint name="r_thumb_phal_3_joint_fix" type="fixed">
    <origin rpy="-5.7918E-16 -5.8287E-16 -3.1416" xyz="-0.012935 -0.007 0"/>
    <parent link="r_thumb_phal_3_link"/>
    <child link="r_thumb_phal_3_link_fix"/>
    <axis xyz="0 0 0"/>
  </joint>

</robot>
