
<?xml version="1.0" ?>
<!-- =================================================================================== -->
<!-- |    This document was autogenerated by xacro from vizzy_description/robots/vizzy_hand_only.urdf.xacro | -->
<!-- |    EDITING THIS FILE BY HAND IS NOT RECOMMENDED                                 | -->
<!-- =================================================================================== -->
<robot name="vizzy_hand" xmlns:controller="http://playerstage.sourceforge.net/gazebo/xmlschema/#controller" xmlns:interface="http://playerstage.sourceforge.net/gazebo/xmlschema/#interface" xmlns:sensor="http://playerstage.sourceforge.net/gazebo/xmlschema/#sensor" xmlns:xacro="http://ros.org/wiki/xacro">

  <!-- Transmissions -->
  <transmission name="r_min_phal_1_transmission">
    <type>transmission_interface/SimpleTransmission</type>
    <joint name="r_min_phal_1_joint">
      <hardwareInterface>hardware_interface/VelocityJointInterface</hardwareInterface>
    </joint>
    <actuator name="r_min_phal_1_motor">
      <mechanicalReduction>1</mechanicalReduction>
    </actuator>
  </transmission>
  <transmission name="r_med_phal_1_transmission">
    <type>transmission_interface/SimpleTransmission</type>
    <joint name="r_med_phal_1_joint">
      <hardwareInterface>hardware_interface/VelocityJointInterface</hardwareInterface>
    </joint>
    <actuator name="r_med_phal_1_motor">
      <mechanicalReduction>1</mechanicalReduction>
    </actuator>
  </transmission>
  <transmission name="r_med_phal_2_transmission">
    <type>transmission_interface/SimpleTransmission</type>
    <joint name="r_med_phal_2_joint">
      <hardwareInterface>hardware_interface/VelocityJointInterface</hardwareInterface>
    </joint>
    <actuator name="r_med_phal_2_motor">
      <mechanicalReduction>1</mechanicalReduction>
    </actuator>
  </transmission>
  <transmission name="r_med_phal_3_transmission">
    <type>transmission_interface/SimpleTransmission</type>
    <joint name="r_med_phal_3_joint">
      <hardwareInterface>hardware_interface/VelocityJointInterface</hardwareInterface>
    </joint>
    <actuator name="r_med_phal_3_motor">
      <mechanicalReduction>1</mechanicalReduction>
    </actuator>
  </transmission>
  <transmission name="r_ind_phal_1_transmission">
    <type>transmission_interface/SimpleTransmission</type>
    <joint name="r_ind_phal_1_joint">
      <hardwareInterface>hardware_interface/VelocityJointInterface</hardwareInterface>
    </joint>
    <actuator name="r_ind_phal_1_motor">
      <mechanicalReduction>1</mechanicalReduction>
    </actuator>
  </transmission>
  <transmission name="r_ind_phal_2_transmission">
    <type>transmission_interface/SimpleTransmission</type>
    <joint name="r_ind_phal_2_joint">
      <hardwareInterface>hardware_interface/VelocityJointInterface</hardwareInterface>
    </joint>
    <actuator name="r_ind_phal_2_motor">
      <mechanicalReduction>1</mechanicalReduction>
    </actuator>
  </transmission>
  <transmission name="r_ind_phal_3_transmission">
    <type>transmission_interface/SimpleTransmission</type>
    <joint name="r_ind_phal_3_joint">
      <hardwareInterface>hardware_interface/VelocityJointInterface</hardwareInterface>
    </joint>
    <actuator name="r_ind_phal_3_motor">
      <mechanicalReduction>1</mechanicalReduction>
    </actuator>
  </transmission>
  <transmission name="r_thumb_phal_1_transmission">
    <type>transmission_interface/SimpleTransmission</type>
    <joint name="r_thumb_phal_1_joint">
      <hardwareInterface>hardware_interface/VelocityJointInterface</hardwareInterface>
    </joint>
    <actuator name="r_thumb_phal_1_motor">
      <mechanicalReduction>1</mechanicalReduction>
    </actuator>
  </transmission>
  <transmission name="r_thumb_phal_2_transmission">
    <type>transmission_interface/SimpleTransmission</type>
    <joint name="r_thumb_phal_2_joint">
      <hardwareInterface>hardware_interface/VelocityJointInterface</hardwareInterface>
    </joint>
    <actuator name="r_thumb_phal_2_motor">
      <mechanicalReduction>1</mechanicalReduction>
    </actuator>
  </transmission>
  <transmission name="r_thumb_phal_3_transmission">
    <type>transmission_interface/SimpleTransmission</type>
    <joint name="r_thumb_phal_3_joint">
      <hardwareInterface>hardware_interface/VelocityJointInterface</hardwareInterface>
    </joint>
    <actuator name="r_thumb_phal_3_motor">
      <mechanicalReduction>1</mechanicalReduction>
    </actuator>
  </transmission>

  <!-- Root link, on the ground just below the robot origin -->
  <link name="base_footprint">
  </link>
  <link name="r_hand_base_link">
    <inertial>
      <origin rpy="0 0 0" xyz="-0.00674439077967622 -0.00586648543041128 0.00390957138640023"/>
      <mass value="0.151046673988997"/>
      <inertia ixx="0.000146470772741843" ixy="1.43292089666054E-06" ixz="2.07342201265105E-05" iyy="0.00022421320055357" iyz="2.70250923997076E-06" izz="9.93519010859762E-05"/>
    </inertial>
    <visual>
      <origin rpy="0 0 0" xyz="0 0 0"/>
      <geometry>
        <mesh filename="package://vizzy_description/meshes/hand/r_hand_base_link.STL"/>
      </geometry>
    </visual>
    <collision>
      <origin rpy="0 0 0" xyz="0 0 0"/>
      <geometry>
        <mesh filename="package://vizzy_description/meshes/hand/r_hand_base_link.STL"/>
      </geometry>
    </collision>
  </link>
  <joint name="r_hand_base_joint_fix" type="fixed">
    <origin rpy="1.5707963268 0 0" xyz="0.007 -0.076 0.009"/>
    <parent link="base_footprint"/>
    <child link="r_hand_base_link"/>
    <axis xyz="0 0 0"/>
  </joint>
  <link name="r_min_phal_1_link">
    <inertial>
      <origin rpy="0 0 0" xyz="-0.0178212692703573 0.000338633799509282 -8.48495256814547E-06"/>
      <mass value="0.0123116066856987"/>
      <inertia ixx="4.19810828425124E-07" ixy="-8.28056937395445E-09" ixz="-1.27867316658423E-10" iyy="1.33241779844217E-06" iyz="3.84070099097823E-10" izz="1.31758404800717E-06"/>
    </inertial>
    <visual>
      <origin rpy="0 0 0" xyz="0 0 0"/>
      <geometry>
        <mesh filename="package://vizzy_description/meshes/hand/r_min_phal_1_link.STL"/>
      </geometry>
    </visual>
    <collision>
      <origin rpy="0 0 0" xyz="0 0 0"/>
      <geometry>
        <mesh filename="package://vizzy_description/meshes/hand/r_min_phal_1_link.STL"/>
      </geometry>
    </collision>
  </link>
  <joint name="r_min_phal_1_joint" type="revolute">
    <origin rpy="5.9237E-16 1.3963 -3.1416" xyz="0.02708 -0.005836 0.043291"/>
    <parent link="r_hand_base_link"/>
    <child link="r_min_phal_1_link"/>
    <axis xyz="0 0 1"/>
    <limit effort="0" lower="0" upper="1.57" velocity="0"/>
  </joint>
  <link name="r_min_phal_1_link_fix">
    <inertial>
      <origin rpy="0 0 0" xyz="-0.00172879723518149 0.00767822711194729 0.000629124810377732"/>
      <mass value="0.00282550462257503"/>
      <inertia ixx="2.01497129990919E-07" ixy="-2.16240614332529E-08" ixz="-5.9411620504755E-08" iyy="1.72890117193849E-07" iyz="2.30807929346573E-08" izz="1.1787689505335E-07"/>
    </inertial>
    <visual>
      <origin rpy="0 0 0" xyz="0 0 0"/>
      <geometry>
        <mesh filename="package://vizzy_description/meshes/hand/r_min_phal_1_link_fix.STL"/>
      </geometry>
      <material name="">
        <color rgba="0.776470588235294 0.756862745098039 0.737254901960784 1"/>
      </material>
    </visual>
    <collision>
      <origin rpy="0 0 0" xyz="0 0 0"/>
      <geometry>
        <mesh filename="package://vizzy_description/meshes/hand/r_min_phal_1_link_fix.STL"/>
      </geometry>
    </collision>
  </link>
  <joint name="r_min_phal_1_joint_fix" type="fixed">
    <origin rpy="1.9199 2.6299E-16 1.5708" xyz="-0.033 0 -0.007"/>
    <parent link="r_min_phal_1_link"/>
    <child link="r_min_phal_1_link_fix"/>
    <axis xyz="0 0 0"/>
  </joint>
  <link name="r_min_phal_2_link">
    <inertial>
      <origin rpy="0 0 0" xyz="-0.0146794976295984 0.000321778454853604 -1.60585011899847E-05"/>
      <mass value="0.00935905263397592"/>
      <inertia ixx="3.25448973931958E-07" ixy="-7.67927676966644E-09" ixz="-2.9191443631579E-10" iyy="7.82460629612252E-07" iyz="5.74854295945301E-10" izz="7.70225783044348E-07"/>
    </inertial>
    <visual>
      <origin rpy="0 0 0" xyz="0 0 0"/>
      <geometry>
        <mesh filename="package://vizzy_description/meshes/hand/r_min_phal_2_link.STL"/>
      </geometry>
    </visual>
    <collision>
      <origin rpy="0 0 0" xyz="0 0 0"/>
      <geometry>
        <mesh filename="package://vizzy_description/meshes/hand/r_min_phal_2_link.STL"/>
      </geometry>
    </collision>
  </link>
  <joint name="r_min_phal_2_joint" type="revolute">
    <origin rpy="-3.1416 -1.2217 1.5708" xyz="0 0.0065778 -0.0023941"/>
    <parent link="r_min_phal_1_link_fix"/>
    <child link="r_min_phal_2_link"/>
    <axis xyz="0 0 1"/>
    <limit effort="0" lower="0" upper="1.57" velocity="0"/>
  </joint>
  <link name="r_min_phal_2_link_fix">
    <inertial>
      <origin rpy="0 0 0" xyz="0.0010334993568897 0.00697346811741158 -0.0017476111791478"/>
      <mass value="0.00257761474790775"/>
      <inertia ixx="1.23080849742913E-07" ixy="-4.87336484234736E-10" ixz="-3.10924773578249E-08" iyy="9.043294654538E-08" iyz="-2.75926783373469E-11" izz="9.21929606188833E-08"/>
    </inertial>
    <visual>
      <origin rpy="0 0 0" xyz="0 0 0"/>
      <geometry>
        <mesh filename="package://vizzy_description/meshes/hand/r_min_phal_2_link_fix.STL"/>
      </geometry>
      <material name="">
        <color rgba="0.776470588235294 0.756862745098039 0.737254901960784 1"/>
      </material>
    </visual>
    <collision>
      <origin rpy="0 0 0" xyz="0 0 0"/>
      <geometry>
        <mesh filename="package://vizzy_description/meshes/hand/r_min_phal_2_link_fix.STL"/>
      </geometry>
    </collision>
  </link>
  <joint name="r_min_phal_2_joint_fix" type="fixed">
    <origin rpy="1.5865 -4.3103E-10 -1.5708" xyz="-0.0265 0 -0.007"/>
    <parent link="r_min_phal_2_link"/>
    <child link="r_min_phal_2_link_fix"/>
    <axis xyz="0 0 0"/>
  </joint>
  <link name="r_min_phal_3_link">
    <inertial>
      <origin rpy="0 0 0" xyz="-0.0125548646076213 0.00056252141125331 -1.90458985400675E-05"/>
      <mass value="0.00838713757871326"/>
      <inertia ixx="2.605055677365E-07" ixy="-2.79008592685343E-08" ixz="1.74761643269228E-10" iyy="4.40992543732785E-07" iyz="6.25455793840317E-10" izz="4.4547901908355E-07"/>
    </inertial>
    <visual>
      <origin rpy="0 0 0" xyz="0 0 0"/>
      <geometry>
        <mesh filename="package://vizzy_description/meshes/hand/r_min_phal_3_link.STL"/>
      </geometry>
    </visual>
    <collision>
      <origin rpy="0 0 0" xyz="0 0 0"/>
      <geometry>
        <mesh filename="package://vizzy_description/meshes/hand/r_min_phal_3_link.STL"/>
      </geometry>
    </collision>
  </link>
  <joint name="r_min_phal_3_joint" type="revolute">
    <origin rpy="3.1416 1.5551 -1.5708" xyz="0 0.0069991 -0.0001097"/>
    <parent link="r_min_phal_2_link_fix"/>
    <child link="r_min_phal_3_link"/>
    <axis xyz="0 0 1"/>
    <limit effort="0" lower="0" upper="1.57" velocity="0"/>
  </joint>
  <link name="r_min_phal_3_link_fix">
    <inertial>
      <origin rpy="0 0 0" xyz="0.00766697975732332 -0.00206053521596537 -2.63862834359863E-10"/>
      <mass value="0.000998337750354602"/>
      <inertia ixx="2.82919971314098E-08" ixy="-1.55555318455011E-08" ixz="-6.97274840902736E-14" iyy="3.53807332969241E-08" iyz="6.32381445979623E-14" izz="4.58877789429413E-08"/>
    </inertial>
    <visual>
      <origin rpy="0 0 0" xyz="0 0 0"/>
      <geometry>
        <mesh filename="package://vizzy_description/meshes/hand/r_min_phal_3_link_fix.STL"/>
      </geometry>
      <material name="">
        <color rgba="1 1 1 1"/>
      </material>
    </visual>
    <collision>
      <origin rpy="0 0 0" xyz="0 0 0"/>
      <geometry>
        <mesh filename="package://vizzy_description/meshes/hand/r_min_phal_3_link_fix.STL"/>
      </geometry>
    </collision>
  </link>
  <joint name="r_min_phal_3_joint_fix" type="fixed">
    <origin rpy="-3.8201E-16 -4.7184E-16 3.1416" xyz="-0.012935 -0.007 0"/>
    <parent link="r_min_phal_3_link"/>
    <child link="r_min_phal_3_link_fix"/>
    <axis xyz="0 0 0"/>
  </joint>
  <link name="r_med_phal_1_link">
    <inertial>
      <origin rpy="0 0 0" xyz="-0.0178212708626085 0.00033863383153541 -8.48395056713422E-06"/>
      <mass value="0.0123116051705352"/>
      <inertia ixx="4.19810810233748E-07" ixy="-8.28056765730354E-09" ixz="-1.27794118562992E-10" iyy="1.33241758331684E-06" iyz="3.84058346750532E-10" izz="1.31758380807131E-06"/>
    </inertial>
    <visual>
      <origin rpy="0 0 0" xyz="0 0 0"/>
      <geometry>
        <mesh filename="package://vizzy_description/meshes/hand/r_med_phal_1_link.STL"/>
      </geometry>
    </visual>
    <collision>
      <origin rpy="0 0 0" xyz="0 0 0"/>
      <geometry>
        <mesh filename="package://vizzy_description/meshes/hand/r_med_phal_1_link.STL"/>
      </geometry>
    </collision>
  </link>
  <joint name="r_med_phal_1_joint" type="revolute">
    <origin rpy="3.1416 1.5708 0" xyz="-0.0029168 -0.005836 0.050139"/>
    <parent link="r_hand_base_link"/>
    <child link="r_med_phal_1_link"/>
    <axis xyz="0 0 1"/>
    <limit effort="0" lower="0" upper="1.57" velocity="0"/>
  </joint>
  <link name="r_med_phal_1_link_fix">
    <inertial>
      <origin rpy="0 0 0" xyz="0.00172879723518197 -0.007 0.00321729227918063"/>
      <mass value="0.00282550462257504"/>
      <inertia ixx="2.01497129990919E-07" ixy="-3.77329290429336E-21" ixz="6.32245259679355E-08" iyy="1.81290840403137E-07" iyz="-4.38995011730441E-15" izz="1.09476171844062E-07"/>
    </inertial>
    <visual>
      <origin rpy="0 0 0" xyz="0 0 0"/>
      <geometry>
        <mesh filename="package://vizzy_description/meshes/hand/r_med_phal_1_link_fix.STL"/>
      </geometry>
      <material name="">
        <color rgba="0.776470588235294 0.756862745098039 0.737254901960784 1"/>
      </material>
    </visual>
    <collision>
      <origin rpy="0 0 0" xyz="0 0 0"/>
      <geometry>
        <mesh filename="package://vizzy_description/meshes/hand/r_med_phal_1_link_fix.STL"/>
      </geometry>
    </collision>
  </link>
  <joint name="r_med_phal_1_joint_fix" type="fixed">
    <origin rpy="-1.5708 -3.5772E-17 -1.5708" xyz="-0.033 0 -0.007"/>
    <parent link="r_med_phal_1_link"/>
    <child link="r_med_phal_1_link_fix"/>
    <axis xyz="0 0 0"/>
  </joint>
  <link name="r_med_phal_2_link">
    <inertial>
      <origin rpy="0 0 0" xyz="-0.0146795000576953 0.00032177866456654 -1.60575358664678E-05"/>
      <mass value="0.00935905088241303"/>
      <inertia ixx="3.25448959273416E-07" ixy="-7.67926075575301E-09" ixz="-2.91863003805203E-10" iyy="7.82460450623358E-07" iyz="5.74844656431998E-10" izz="7.70225580712677E-07"/>
    </inertial>
    <visual>
      <origin rpy="0 0 0" xyz="0 0 0"/>
      <geometry>
        <mesh filename="package://vizzy_description/meshes/hand/r_med_phal_2_link.STL"/>
      </geometry>
    </visual>
    <collision>
      <origin rpy="0 0 0" xyz="0 0 0"/>
      <geometry>
        <mesh filename="package://vizzy_description/meshes/hand/r_med_phal_2_link.STL"/>
      </geometry>
    </collision>
  </link>
  <joint name="r_med_phal_2_joint" type="revolute">
    <origin rpy="1.5708 -1.5708 0" xyz="0 -0.007 0"/>
    <parent link="r_med_phal_1_link_fix"/>
    <child link="r_med_phal_2_link"/>
    <axis xyz="0 0 1"/>
    <limit effort="0" lower="0" upper="1.57" velocity="0"/>
  </joint>
  <link name="r_med_phal_2_link_fix">
    <inertial>
      <origin rpy="0 0 0" xyz="0.0118618906099283 -0.00596650062172834 -3.46944695195361E-17"/>
      <mass value="0.00257761474790776"/>
      <inertia ixx="9.21933940240852E-08" ixy="-3.10962967844791E-08" ixz="1.51647342295295E-16" iyy="1.23080848816559E-07" iyz="2.59560149671808E-21" izz="9.04325140665312E-08"/>
    </inertial>
    <visual>
      <origin rpy="0 0 0" xyz="0 0 0"/>
      <geometry>
        <mesh filename="package://vizzy_description/meshes/hand/r_med_phal_2_link_fix.STL"/>
      </geometry>
      <material name="">
        <color rgba="1 1 1 1"/>
      </material>
    </visual>
    <collision>
      <origin rpy="0 0 0" xyz="0 0 0"/>
      <geometry>
        <mesh filename="package://vizzy_description/meshes/hand/r_med_phal_2_link_fix.STL"/>
      </geometry>
    </collision>
  </link>
  <joint name="r_med_phal_2_joint_fix" type="fixed">
    <origin rpy="1.0462E-16 5.3776E-17 -3.1416" xyz="-0.013 -0.007 0"/>
    <parent link="r_med_phal_2_link"/>
    <child link="r_med_phal_2_link_fix"/>
    <axis xyz="0 0 0"/>
  </joint>
  <link name="r_med_phal_3_link">
    <inertial>
      <origin rpy="0 0 0" xyz="-0.0125548659012441 0.000562521495778267 -1.90455588882231E-05"/>
      <mass value="0.00838713661986737"/>
      <inertia ixx="2.60505554768481E-07" ixy="-2.79008518020945E-08" ixz="1.74801618678154E-10" iyy="4.40992441430368E-07" iyz="6.25441468356982E-10" izz="4.45478908833015E-07"/>
    </inertial>
    <visual>
      <origin rpy="0 0 0" xyz="0 0 0"/>
      <geometry>
        <mesh filename="package://vizzy_description/meshes/hand/r_med_phal_3_link.STL"/>
      </geometry>
    </visual>
    <collision>
      <origin rpy="0 0 0" xyz="0 0 0"/>
      <geometry>
        <mesh filename="package://vizzy_description/meshes/hand/r_med_phal_3_link.STL"/>
      </geometry>
    </collision>
  </link>
  <joint name="r_med_phal_3_joint" type="revolute">
    <origin rpy="1.9583E-16 -1.6827E-16 3.1416" xyz="0.0135 -0.007 0"/>
    <parent link="r_med_phal_2_link_fix"/>
    <child link="r_med_phal_3_link"/>
    <axis xyz="0 0 1"/>
    <limit effort="0" lower="0" upper="1.57" velocity="0"/>
  </joint>
  <link name="r_med_phal_3_link_fix">
    <inertial>
      <origin rpy="0 0 0" xyz="0.00766698043437972 -0.00206054063651943 4.34120471341781E-10"/>
      <mass value="0.000998338186733994"/>
      <inertia ixx="2.85389333670696E-08" ixy="-1.55555455969206E-08" ixz="-6.81506763278708E-14" iyy="3.56276792086196E-08" iyz="6.51445299490191E-14" izz="4.5887818729762E-08"/>
    </inertial>
    <visual>
      <origin rpy="0 0 0" xyz="0 0 0"/>
      <geometry>
        <mesh filename="package://vizzy_description/meshes/hand/r_med_phal_3_link_fix.STL"/>
      </geometry>
      <material name="">
        <color rgba="1 1 1 1"/>
      </material>
    </visual>
    <collision>
      <origin rpy="0 0 0" xyz="0 0 0"/>
      <geometry>
        <mesh filename="package://vizzy_description/meshes/hand/r_med_phal_3_link_fix.STL"/>
      </geometry>
    </collision>
  </link>
  <joint name="r_med_phal_3_joint_fix" type="fixed">
    <origin rpy="-2.1011E-17 2.6541E-16 3.1416" xyz="-0.012935 -0.007 0"/>
    <parent link="r_med_phal_3_link"/>
    <child link="r_med_phal_3_link_fix"/>
    <axis xyz="0 0 0"/>
  </joint>
  <link name="r_ind_phal_1_link">
    <inertial>
      <origin rpy="0 0 0" xyz="-0.0178212707905891 0.000338633378830417 -8.48312003929111E-06"/>
      <mass value="0.0123116032374656"/>
      <inertia ixx="4.19810810567381E-07" ixy="-8.28060582485729E-09" ixz="-1.27740583343495E-10" iyy="1.3324175993775E-06" iyz="3.84048264805675E-10" izz="1.31758383563722E-06"/>
    </inertial>
    <visual>
      <origin rpy="0 0 0" xyz="0 0 0"/>
      <geometry>
        <mesh filename="package://vizzy_description/meshes/hand/r_ind_phal_1_link.STL"/>
      </geometry>
    </visual>
    <collision>
      <origin rpy="0 0 0" xyz="0 0 0"/>
      <geometry>
        <mesh filename="package://vizzy_description/meshes/hand/r_ind_phal_1_link.STL"/>
      </geometry>
    </collision>
  </link>
  <joint name="r_ind_phal_1_joint" type="revolute">
    <origin rpy="-3.1416 1.3963 1.3526E-15" xyz="-0.031914 -0.005836 0.045408"/>
    <parent link="r_hand_base_link"/>
    <child link="r_ind_phal_1_link"/>
    <axis xyz="0 0 1"/>
    <limit effort="0" lower="0" upper="1.57" velocity="0"/>
  </joint>
  <link name="r_ind_phal_1_link_fix">
    <inertial>
      <origin rpy="0 0 0" xyz="-0.00172879723518416 0.00547746957905566 0.00541740681693609"/>
      <mass value="0.00282550462257504"/>
      <inertia ixx="2.01497129990917E-07" ixy="2.16240614332436E-08" ixz="-5.94116205047253E-08" iyy="1.72890122837423E-07" iyz="-2.30807862088648E-08" izz="1.17876889409708E-07"/>
    </inertial>
    <visual>
      <origin rpy="0 0 0" xyz="0 0 0"/>
      <geometry>
        <mesh filename="package://vizzy_description/meshes/hand/r_ind_phal_1_link_fix.STL"/>
      </geometry>
      <material name="">
        <color rgba="0.776470588235294 0.756862745098039 0.737254901960784 1"/>
      </material>
    </visual>
    <collision>
      <origin rpy="0 0 0" xyz="0 0 0"/>
      <geometry>
        <mesh filename="package://vizzy_description/meshes/hand/r_ind_phal_1_link_fix.STL"/>
      </geometry>
    </collision>
  </link>
  <joint name="r_ind_phal_1_joint_fix" type="fixed">
    <origin rpy="1.2217 -3.1139E-16 1.5708" xyz="-0.033 0 -0.007"/>
    <parent link="r_ind_phal_1_link"/>
    <child link="r_ind_phal_1_link_fix"/>
    <axis xyz="0 0 0"/>
  </joint>
  <link name="r_ind_phal_2_link">
    <inertial>
      <origin rpy="0 0 0" xyz="-0.0146795003248846 0.000321778719691427 -1.60569463318223E-05"/>
      <mass value="0.00935904736941848"/>
      <inertia ixx="3.25448942816778E-07" ixy="-7.67927393287117E-09" ixz="-2.91829328070861E-10" iyy="7.82460460014294E-07" iyz="5.74841846680195E-10" izz="7.70225589038738E-07"/>
    </inertial>
    <visual>
      <origin rpy="0 0 0" xyz="0 0 0"/>
      <geometry>
        <mesh filename="package://vizzy_description/meshes/hand/r_ind_phal_2_link.STL"/>
      </geometry>
    </visual>
    <collision>
      <origin rpy="0 0 0" xyz="0 0 0"/>
      <geometry>
        <mesh filename="package://vizzy_description/meshes/hand/r_ind_phal_2_link.STL"/>
      </geometry>
    </collision>
  </link>
  <joint name="r_ind_phal_2_joint" type="revolute">
    <origin rpy="4.8212E-17 -1.2217 -1.5708" xyz="0 0.0065778 0.0023941"/>
    <parent link="r_ind_phal_1_link_fix"/>
    <child link="r_ind_phal_2_link"/>
    <axis xyz="0 0 1"/>
    <limit effort="0" lower="0" upper="1.57" velocity="0"/>
  </joint>
  <link name="r_ind_phal_2_link_fix">
    <inertial>
      <origin rpy="0 0 0" xyz="0.0118618906099286 -0.00596650062172362 -1.04083408558608E-16"/>
      <mass value="0.00257761474790776"/>
      <inertia ixx="9.21933940240599E-08" ixy="-3.10962967844598E-08" ixz="1.51647441907098E-16" iyy="1.23080848816561E-07" iyz="2.37235399680208E-21" izz="9.04325140665081E-08"/>
    </inertial>
    <visual>
      <origin rpy="0 0 0" xyz="0 0 0"/>
      <geometry>
        <mesh filename="package://vizzy_description/meshes/hand/r_ind_phal_2_link_fix.STL"/>
      </geometry>
      <material name="">
        <color rgba="1 1 1 1"/>
      </material>
    </visual>
    <collision>
      <origin rpy="0 0 0" xyz="0 0 0"/>
      <geometry>
        <mesh filename="package://vizzy_description/meshes/hand/r_ind_phal_2_link_fix.STL"/>
      </geometry>
    </collision>
  </link>
  <joint name="r_ind_phal_2_joint_fix" type="fixed">
    <origin rpy="-5.6682E-17 -4.7184E-16 -3.1416" xyz="-0.013 -0.007 0"/>
    <parent link="r_ind_phal_2_link"/>
    <child link="r_ind_phal_2_link_fix"/>
    <axis xyz="0 0 0"/>
  </joint>
  <link name="r_ind_phal_3_link">
    <inertial>
      <origin rpy="0 0 0" xyz="-0.012554864593053 0.000562522193847176 -1.90456569425131E-05"/>
      <mass value="0.00838713389782705"/>
      <inertia ixx="2.60505527476575E-07" ixy="-2.79009123592796E-08" ixz="1.74839156347342E-10" iyy="4.40992467798346E-07" iyz="6.25434072315469E-10" izz="4.45478930576092E-07"/>
    </inertial>
    <visual>
      <origin rpy="0 0 0" xyz="0 0 0"/>
      <geometry>
        <mesh filename="package://vizzy_description/meshes/hand/r_ind_phal_3_link.STL"/>
      </geometry>
    </visual>
    <collision>
      <origin rpy="0 0 0" xyz="0 0 0"/>
      <geometry>
        <mesh filename="package://vizzy_description/meshes/hand/r_ind_phal_3_link.STL"/>
      </geometry>
    </collision>
  </link>
  <joint name="r_ind_phal_3_joint" type="revolute">
    <origin rpy="-1.8552E-16 -6.6613E-16 -3.1416" xyz="0.0135 -0.007 0"/>
    <parent link="r_ind_phal_2_link_fix"/>
    <child link="r_ind_phal_3_link"/>
    <axis xyz="0 0 1"/>
    <limit effort="0" lower="0" upper="1.57" velocity="0"/>
  </joint>
  <link name="r_ind_phal_3_link_fix">
    <inertial>
      <origin rpy="0 0 0" xyz="0.00766697974840633 -0.00206053520748256 1.56308629581381E-09"/>
      <mass value="0.000998337750144567"/>
      <inertia ixx="2.82350950065839E-08" ixy="-1.5555531848229E-08" ixz="-6.77122345303158E-14" iyy="3.53238314091707E-08" iyz="6.21765815672305E-14" izz="4.58877791485407E-08"/>
    </inertial>
    <visual>
      <origin rpy="0 0 0" xyz="0 0 0"/>
      <geometry>
        <mesh filename="package://vizzy_description/meshes/hand/r_ind_phal_3_link_fix.STL"/>
      </geometry>
      <material name="">
        <color rgba="1 1 1 1"/>
      </material>
    </visual>
    <collision>
      <origin rpy="0 0 0" xyz="0 0 0"/>
      <geometry>
        <mesh filename="package://vizzy_description/meshes/hand/r_ind_phal_3_link_fix.STL"/>
      </geometry>
    </collision>
  </link>
  <joint name="r_ind_phal_3_joint_fix" type="fixed">
    <origin rpy="-1.8552E-16 -6.3838E-16 3.1416" xyz="-0.012935 -0.007 0"/>
    <parent link="r_ind_phal_3_link"/>
    <child link="r_ind_phal_3_link_fix"/>
    <axis xyz="0 0 0"/>
  </joint>
  <link name="r_thumb_phal_1_link">
    <inertial>
      <origin rpy="0 0 0" xyz="-0.00627940633196827 8.3796886192861E-05 7.22744895452834E-05"/>
      <mass value="0.00234087705696458"/>
      <inertia ixx="6.42086690069036E-08" ixy="9.1675772237601E-10" ixz="-6.88811649213738E-10" iyy="5.92649073898386E-08" iyz="-6.66151305802011E-10" izz="7.04099770735268E-08"/>
    </inertial>
    <visual>
      <origin rpy="0 0 0" xyz="0 0 0"/>
      <geometry>
        <mesh filename="package://vizzy_description/meshes/hand/r_thumb_phal_1_link.STL"/>
      </geometry>
    </visual>
    <collision>
      <origin rpy="0 0 0" xyz="0 0 0"/>
      <geometry>
        <mesh filename="package://vizzy_description/meshes/hand/r_thumb_phal_1_link.STL"/>
      </geometry>
    </collision>
  </link>
  <joint name="r_thumb_phal_1_joint" type="revolute">
    <origin rpy="3.0577 0.30311 -0.27462" xyz="-0.043854 -0.005836 -0.020232"/>
    <parent link="r_hand_base_link"/>
    <child link="r_thumb_phal_1_link"/>
    <axis xyz="0 0 1"/>
    <limit effort="0" lower="0" upper="1.57" velocity="0"/>
  </joint>
  <link name="r_thumb_phal_1_link_fix">
    <inertial>
      <origin rpy="0 0 0" xyz="1.46236201984517E-05 0.000373790067287619 0.00197982203155241"/>
      <mass value="0.00643378340618347"/>
      <inertia ixx="2.37679767346839E-07" ixy="-9.97525106818169E-11" ixz="-6.13755302817216E-10" iyy="3.17726876181191E-07" iyz="-6.09062343597853E-09" izz="2.34558855837791E-07"/>
    </inertial>
    <visual>
      <origin rpy="0 0 0" xyz="0 0 0"/>
      <geometry>
        <mesh filename="package://vizzy_description/meshes/hand/r_thumb_phal_1_link_fix.STL"/>
      </geometry>
    </visual>
    <collision>
      <origin rpy="0 0 0" xyz="0 0 0"/>
      <geometry>
        <mesh filename="package://vizzy_description/meshes/hand/r_thumb_phal_1_link_fix.STL"/>
      </geometry>
    </collision>
  </link>
  <joint name="r_thumb_phal_1_joint_fix" type="fixed">
    <origin rpy="1.5708 -3.1765E-16 -1.5708" xyz="-0.0175 0 0"/>
    <parent link="r_thumb_phal_1_link"/>
    <child link="r_thumb_phal_1_link_fix"/>
    <axis xyz="0 0 0"/>
  </joint>
  <link name="r_thumb_phal_2_link">
    <inertial>
      <origin rpy="0 0 0" xyz="-0.0178212712750334 0.000338633445431731 -8.4829403080508E-06"/>
      <mass value="0.0123116014240311"/>
      <inertia ixx="4.19810804750257E-07" ixy="-8.28057330562904E-09" ixz="-1.27735483599834E-10" iyy="1.33241755564903E-06" iyz="3.84041886468474E-10" izz="1.31758378214817E-06"/>
    </inertial>
    <visual>
      <origin rpy="0 0 0" xyz="0 0 0"/>
      <geometry>
        <mesh filename="package://vizzy_description/meshes/hand/r_thumb_phal_2_link.STL"/>
      </geometry>
    </visual>
    <collision>
      <origin rpy="0 0 0" xyz="0 0 0"/>
      <geometry>
        <mesh filename="package://vizzy_description/meshes/hand/r_thumb_phal_2_link.STL"/>
      </geometry>
    </collision>
  </link>
  <joint name="r_thumb_phal_2_joint" type="revolute">
    <origin rpy="-1.5708 1.5661 -1.5708" xyz="0 0 0.005"/>
    <parent link="r_thumb_phal_1_link_fix"/>
    <child link="r_thumb_phal_2_link"/>
    <axis xyz="0 0 1"/>
    <limit effort="0" lower="0" upper="1.57" velocity="0"/>
  </joint>
  <link name="r_thumb_phal_2_link_fix">
    <inertial>
      <origin rpy="0 0 0" xyz="-0.0130448715272274 -0.0052712081124111 -4.39755627745786E-11"/>
      <mass value="0.00282550279070484"/>
      <inertia ixx="1.09476043021612E-07" ixy="6.29793661939842E-08" ixz="-5.62433696731488E-15" iyy="2.00598910461455E-07" iyz="-1.31721735329064E-16" izz="1.80392567692408E-07"/>
    </inertial>
    <visual>
      <origin rpy="0 0 0" xyz="0 0 0"/>
      <geometry>
        <mesh filename="package://vizzy_description/meshes/hand/r_thumb_phal_2_link_fix.STL"/>
      </geometry>
      <material name="">
        <color rgba="1 1 1 1"/>
      </material>
    </visual>
    <collision>
      <origin rpy="0 0 0" xyz="0 0 0"/>
      <geometry>
        <mesh filename="package://vizzy_description/meshes/hand/r_thumb_phal_2_link_fix.STL"/>
      </geometry>
    </collision>
  </link>
  <joint name="r_thumb_phal_2_joint_fix" type="fixed">
    <origin rpy="3.1416 6.3838E-16 -7.0473E-17" xyz="-0.01675 -0.007 0"/>
    <parent link="r_thumb_phal_2_link"/>
    <child link="r_thumb_phal_2_link_fix"/>
    <axis xyz="0 0 0"/>
  </joint>
  <link name="r_thumb_phal_3_link">
    <inertial>
      <origin rpy="0 0 0" xyz="-0.0125548640176916 0.00056252197857469 -1.90460476551368E-05"/>
      <mass value="0.00838713518345204"/>
      <inertia ixx="2.60505570751336E-07" ixy="-2.79008349627709E-08" ixz="1.74829416361065E-10" iyy="4.40992619187728E-07" iyz="6.2543048992729E-10" izz="4.45479141195201E-07"/>
    </inertial>
    <visual>
      <origin rpy="0 0 0" xyz="0 0 0"/>
      <geometry>
        <mesh filename="package://vizzy_description/meshes/hand/r_thumb_phal_3_link.STL"/>
      </geometry>
    </visual>
    <collision>
      <origin rpy="0 0 0" xyz="0 0 0"/>
      <geometry>
        <mesh filename="package://vizzy_description/meshes/hand/r_thumb_phal_3_link.STL"/>
      </geometry>
    </collision>
  </link>
  <joint name="r_thumb_phal_3_joint" type="revolute">
    <origin rpy="0 0 0" xyz="-0.0332692 0 0"/>
    <parent link="r_thumb_phal_2_link"/>
    <child link="r_thumb_phal_3_link"/>
    <axis xyz="0 0 1"/>
    <limit effort="0" lower="0" upper="1.57" velocity="0"/>
  </joint>
  <link name="r_thumb_phal_3_link_fix">
    <inertial>
      <origin rpy="0 0 0" xyz="0.00766697409984854 -0.00206053700829757 1.96358397597241E-09"/>
      <mass value="0.000998338233225828"/>
      <inertia ixx="2.82420018878066E-08" ixy="-1.55555519770169E-08" ixz="-6.64276685302323E-14" iyy="3.53307383140706E-08" iyz="6.32120231059822E-14" izz="4.58878333785307E-08"/>
    </inertial>
    <visual>
      <origin rpy="0 0 0" xyz="0 0 0"/>
      <geometry>
        <mesh filename="package://vizzy_description/meshes/hand/r_thumb_phal_3_link_fix.STL"/>
      </geometry>
      <material name="">
        <color rgba="1 1 1 1"/>
      </material>
    </visual>
    <collision>
      <origin rpy="0 0 0" xyz="0 0 0"/>
      <geometry>
        <mesh filename="package://vizzy_description/meshes/hand/r_thumb_phal_3_link_fix.STL"/>
      </geometry>
    </collision>
  </link>
  <joint name="r_thumb_phal_3_joint_fix" type="fixed">
    <origin rpy="-5.7918E-16 -5.8287E-16 -3.1416" xyz="-0.012935 -0.007 0"/>
    <parent link="r_thumb_phal_3_link"/>
    <child link="r_thumb_phal_3_link_fix"/>
    <axis xyz="0 0 0"/>
  </joint>

  <!-- Virtual joints for floating behaviour -->
  <link name="world"/>
  <!-- Translation -->
  <joint name="virtual_px_joint" type="prismatic">
    <origin rpy="0 0 0" xyz="0 0 0"/>
    <axis xyz="1 0 0"/>
    <parent link="world"/>
    <child link="virtual_px_link"/>
    <limit effort="40.0" lower="0.0" upper="0.5" velocity="5.0"/>
    <dynamics damping="0.01" friction="0.0"/>
  </joint>
  <link name="virtual_px_link">
    <visual>
      <origin rpy="0 0 0.0" xyz="0 0 0"/>
      <geometry>
        <cylinder length="0.01" radius="0.01"/>
      </geometry>
    </visual>
    <inertial>
      <origin rpy="0 0 0" xyz="0.0 0.0 0.0"/>
      <mass value="0.001"/>
      <inertia ixx="0.01" ixy="0" ixz="0" iyy="0.01" iyz="0" izz="0.01"/>
    </inertial>
    <collision>
      <origin rpy="0 0 0" xyz="0.0 0.0 0.0"/>
      <geometry>
        <cylinder length="0.001" radius="0.01"/>
      </geometry>
    </collision>
  </link>
    <joint name="virtual_py_joint" type="prismatic">
    <origin rpy="0 0 0" xyz="0 0 0"/>
    <axis xyz="0 1 0"/>
    <parent link="virtual_px_link"/>
    <child link="virtual_py_link"/>
    <limit effort="40.0" lower="0.0" upper="0.5" velocity="5.0"/>
    <dynamics damping="0.01" friction="0.0"/>
  </joint>
  <link name="virtual_py_link">
    <visual>
      <origin rpy="0 0 0.0" xyz="0 0 0"/>
      <geometry>
        <cylinder length="0.01" radius="0.01"/>
      </geometry>
    </visual>
    <inertial>
      <origin rpy="0 0 0" xyz="0.0 0.0 0.0"/>
      <mass value="0.001"/>
      <inertia ixx="0.01" ixy="0" ixz="0" iyy="0.01" iyz="0" izz="0.01"/>
    </inertial>
    <collision>
      <origin rpy="0 0 0" xyz="0.0 0.0 0.0"/>
      <geometry>
        <cylinder length="0.001" radius="0.01"/>
      </geometry>
    </collision>
  </link>
    <joint name="virtual_pz_joint" type="prismatic">
    <origin rpy="0 0 0" xyz="0 0 0"/>
    <axis xyz="0 0 1"/>
    <parent link="virtual_py_link"/>
    <child link="virtual_pz_link"/>
    <limit effort="40.0" lower="0.0" upper="0.5" velocity="5.0"/>
    <dynamics damping="0.01" friction="0.0"/>
  </joint>
  <link name="virtual_pz_link">
    <visual>
      <origin rpy="0 0 0.0" xyz="0 0 0"/>
      <geometry>
        <cylinder length="0.01" radius="0.01"/>
      </geometry>
    </visual>
    <inertial>
      <origin rpy="0 0 0" xyz="0.0 0.0 0.0"/>
      <mass value="0.001"/>
      <inertia ixx="0.01" ixy="0" ixz="0" iyy="0.01" iyz="0" izz="0.01"/>
    </inertial>
    <collision>
      <origin rpy="0 0 0" xyz="0.0 0.0 0.0"/>
      <geometry>
        <cylinder length="0.001" radius="0.01"/>
      </geometry>
    </collision>
  </link>

  <!-- Rotation -->
  <joint name="virtual_ry_joint" type="continuous">
    <origin rpy="0 0 0" xyz="0 0 0"/>
    <axis xyz="0 0 1"/>
    <parent link="virtual_pz_link"/>
    <child link="virtual_ry_link"/>
    <limit effort="40.0" velocity="5.0"/>
    <dynamics damping="10000" friction="0.0"/>
  </joint>
  <link name="virtual_ry_link">
    <visual>
      <origin rpy="0 0 0.0" xyz="0 0 0"/>
      <geometry>
        <cylinder length="0.01" radius="0.01"/>
      </geometry>
    </visual>
    <inertial>
      <origin rpy="0 0 0" xyz="0.0 0.0 0.0"/>
      <mass value="0.001"/>
      <inertia ixx="0.01" ixy="0" ixz="0" iyy="0.01" iyz="0" izz="0.01"/>
    </inertial>
    <collision>
      <origin rpy="0 0 0" xyz="0.0 0.0 0.0"/>
      <geometry>
        <cylinder length="0.001" radius="0.01"/>
      </geometry>
    </collision>
  </link>
    <joint name="virtual_rp_joint" type="continuous">
    <origin rpy="0 0 0" xyz="0 0 0"/>
    <axis xyz="0 1 0"/>
    <parent link="virtual_ry_link"/>
    <child link="virtual_rp_link"/>
    <limit effort="40.0" velocity="5.0"/>
    <dynamics damping="10000" friction="0.0"/>
  </joint>
  <link name="virtual_rp_link">
    <visual>
      <origin rpy="0 0 0.0" xyz="0 0 0"/>
      <geometry>
        <cylinder length="0.01" radius="0.01"/>
      </geometry>
    </visual>
    <inertial>
      <origin rpy="0 0 0" xyz="0.0 0.0 0.0"/>
      <mass value="0.001"/>
      <inertia ixx="0.01" ixy="0" ixz="0" iyy="0.01" iyz="0" izz="0.01"/>
    </inertial>
    <collision>
      <origin rpy="0 0 0" xyz="0.0 0.0 0.0"/>
      <geometry>
        <cylinder length="0.001" radius="0.01"/>
      </geometry>
    </collision>
  </link>
    <joint name="virtual_rr_joint" type="continuous">
    <origin rpy="0 0 0" xyz="0 0 0"/>
    <axis xyz="1 0 0"/>
    <parent link="virtual_rp_link"/>
    <child link="base_footprint"/>
    <limit effort="40.0" velocity="5.0"/>
    <dynamics damping="10000" friction="0.0"/>
  </joint>

  <!-- Gazebo gripper plugin -->
  <gazebo>
    <plugin name="hand_plugin" filename="libHandPlugin.so">
      <!-- Reference names -->
      <model>vizzy_right_hand</model>
      <!-- Virtual joints for floating behaviour -->
      <virtualJoints>
        virtual_px_joint
        virtual_py_joint
        virtual_pz_joint
        virtual_rr_joint
        virtual_rp_joint
        virtual_ry_joint
      </virtualJoints>
      <!-- Constraints -->
      <gravity>0</gravity>
    </plugin>
  </gazebo>

</robot>

